<?xml version="1.0" ?>
<!-- =================================================================================== -->
<!-- |    This document was autogenerated by xacro from robomaster_ep.urdf.xacro       | -->
<!-- |    EDITING THIS FILE BY HAND IS NOT RECOMMENDED                                 | -->
<!-- =================================================================================== -->
<robot name="robomaster_ep">
  <link name="base_link"/>
  <link name="chassis_base_link">
    <inertial>
      <origin rpy="0 0 0" xyz="-0.0058789 -0.0001128 0.0294307"/>
      <mass value="100"/>
      <inertia ixx="0.01451" ixy="0" ixz="0" iyy="0.00512" iyz="0" izz="0.01759"/>
    </inertial>
    <visual name="armor">
      <origin rpy="0 0 0" xyz="-0.0064553 -0.078141 0.0292877"/>
      <geometry>
        <mesh filename="../meshes/armor.dae" scale="1.0 1.0 1.0"/>
      </geometry>
      <material name="armor_plastic"/>
    </visual>
    <visual name="battery">
      <origin rpy="0 0 0" xyz="-0.130336 -0.0018702 0.0174177"/>
      <geometry>
        <mesh filename="../meshes/battery.dae" scale="1.0 1.0 1.0"/>
      </geometry>
      <material name="dark_plastic"/>
    </visual>
    <visual name="battery_pin_left">
      <origin rpy="0 0 0" xyz="-0.1158907 0.066115 0.0525243"/>
      <geometry>
        <mesh filename="../meshes/battery_pin_left.dae" scale="1.0 1.0 1.0"/>
      </geometry>
      <material name="dark_plastic"/>
    </visual>
    <visual name="battery_pin_right">
      <origin rpy="0 0 0" xyz="-0.1158907 -0.0658844 0.0525243"/>
      <geometry>
        <mesh filename="../meshes/battery_pin_right.dae" scale="1.0 1.0 1.0"/>
      </geometry>
      <material name="dark_plastic"/>
    </visual>
    <visual name="chassis">
      <origin rpy="0 0 0" xyz="-0.0059039 0.0004154 0.0527955"/>
      <geometry>
        <mesh filename="../meshes/chassis.dae" scale="1.0 1.0 1.0"/>
      </geometry>
      <material name="chassis"/>
    </visual>
    <visual name="controller">
      <origin rpy="0 0 0" xyz="-0.1142288 -0.0006716 0.052675"/>
      <geometry>
        <mesh filename="../meshes/controller.dae" scale="1.0 1.0 1.0"/>
      </geometry>
      <material name="dark_plastic"/>
    </visual>
    <visual name="controller_cover">
      <origin rpy="0 0 0" xyz="-0.0787757 -0.002522 0.0720827"/>
      <geometry>
        <mesh filename="../meshes/controller_cover.dae" scale="1.0 1.0 1.0"/>
      </geometry>
      <material name="cover_plastic"/>
    </visual>
    <collision name="base_collision">
      <origin rpy="0 0 0" xyz="-0.0058789 -0.0001128 0.0294307"/>
      <geometry>
        <mesh filename="../meshes/base_collision.dae" scale="1.0 1.0 1.0"/>
      </geometry>
    </collision>
  </link>
  <joint name="chassis_base_joint" type="fixed">
    <origin rpy="0 0 0" xyz="0 0 0.03465"/>
    <parent link="base_link"/>
    <child link="chassis_base_link"/>
  </joint>
  <link name="front_hit_sensor_link">
    <inertial>
      <origin rpy="0 0 0" xyz="0 0 0"/>
      <mass value="0.001"/>
      <inertia ixx="0.001" ixy="0" ixz="0" iyy="0.001" iyz="0" izz="0.001"/>
    </inertial>
    <visual name="front_hit_sensor">
      <origin rpy="0 0 0" xyz="0 0 0"/>
      <geometry>
        <mesh filename="../meshes/hit_sensor.dae" scale="1.0 1.0 1.0"/>
      </geometry>
      <material name="hit_detector"/>
    </visual>
  </link>
  <link name="front_led_link">
    <inertial>
      <origin rpy="0 0 0" xyz="0 0 0"/>
      <mass value="0.001"/>
      <inertia ixx="0.001" ixy="0" ixz="0" iyy="0.001" iyz="0" izz="0.001"/>
    </inertial>
    <visual name="front_led">
      <origin rpy="0 0 0" xyz="0 0 0"/>
      <geometry>
        <mesh filename="../meshes/led.dae" scale="1.0 1.0 1.0"/>
      </geometry>
      <material name="led_light"/>
    </visual>
  </link>
  <joint name="front_hit_sensor_joint" type="fixed">
    <origin rpy="0 0 0" xyz="0.1569985 -0.0004276 0.0432862"/>
    <parent link="chassis_base_link"/>
    <child link="front_hit_sensor_link"/>
  </joint>
  <joint name="front_led_joint" type="fixed">
    <origin rpy="0 0 0" xyz="0.0087428 -0.0012841 3.75e-05"/>
    <parent link="front_hit_sensor_link"/>
    <child link="front_led_link"/>
  </joint>
  <link name="left_hit_sensor_link">
    <inertial>
      <origin rpy="0 0 0" xyz="0 0 0"/>
      <mass value="0.001"/>
      <inertia ixx="0.001" ixy="0" ixz="0" iyy="0.001" iyz="0" izz="0.001"/>
    </inertial>
    <visual name="left_hit_sensor">
      <origin rpy="0 0 0" xyz="0 0 0"/>
      <geometry>
        <mesh filename="../meshes/hit_sensor.dae" scale="1.0 1.0 1.0"/>
      </geometry>
      <material name="hit_detector"/>
    </visual>
  </link>
  <link name="left_led_link">
    <inertial>
      <origin rpy="0 0 0" xyz="0 0 0"/>
      <mass value="0.001"/>
      <inertia ixx="0.001" ixy="0" ixz="0" iyy="0.001" iyz="0" izz="0.001"/>
    </inertial>
    <visual name="left_led">
      <origin rpy="0 0 0" xyz="0 0 0"/>
      <geometry>
        <mesh filename="../meshes/led.dae" scale="1.0 1.0 1.0"/>
      </geometry>
      <material name="led_light"/>
    </visual>
  </link>
  <joint name="left_hit_sensor_joint" type="fixed">
    <origin rpy="0 0 1.5707963267948966" xyz="-0.0024413 0.0886932 0.0298341"/>
    <parent link="chassis_base_link"/>
    <child link="left_hit_sensor_link"/>
  </joint>
  <joint name="left_led_joint" type="fixed">
    <origin rpy="0 0 0" xyz="0.0087428 -0.0012841 3.75e-05"/>
    <parent link="left_hit_sensor_link"/>
    <child link="left_led_link"/>
  </joint>
  <link name="rear_hit_sensor_link">
    <inertial>
      <origin rpy="0 0 0" xyz="0 0 0"/>
      <mass value="0.001"/>
      <inertia ixx="0.001" ixy="0" ixz="0" iyy="0.001" iyz="0" izz="0.001"/>
    </inertial>
    <visual name="rear_hit_sensor">
      <origin rpy="0 0 0" xyz="0 0 0"/>
      <geometry>
        <mesh filename="../meshes/hit_sensor.dae" scale="1.0 1.0 1.0"/>
      </geometry>
      <material name="hit_detector"/>
    </visual>
  </link>
  <link name="rear_led_link">
    <inertial>
      <origin rpy="0 0 0" xyz="0 0 0"/>
      <mass value="0.001"/>
      <inertia ixx="0.001" ixy="0" ixz="0" iyy="0.001" iyz="0" izz="0.001"/>
    </inertial>
    <visual name="rear_led">
      <origin rpy="0 0 0" xyz="0 0 0"/>
      <geometry>
        <mesh filename="../meshes/led.dae" scale="1.0 1.0 1.0"/>
      </geometry>
      <material name="led_light"/>
    </visual>
  </link>
  <joint name="rear_hit_sensor_joint" type="fixed">
    <origin rpy="0 0 3.141592653589793" xyz="-0.1581827 -0.0027864 0.0303668"/>
    <parent link="chassis_base_link"/>
    <child link="rear_hit_sensor_link"/>
  </joint>
  <joint name="rear_led_joint" type="fixed">
    <origin rpy="0 0 0" xyz="0.0087428 -0.0012841 3.75e-05"/>
    <parent link="rear_hit_sensor_link"/>
    <child link="rear_led_link"/>
  </joint>
  <link name="right_hit_sensor_link">
    <inertial>
      <origin rpy="0 0 0" xyz="0 0 0"/>
      <mass value="0.001"/>
      <inertia ixx="0.001" ixy="0" ixz="0" iyy="0.001" iyz="0" izz="0.001"/>
    </inertial>
    <visual name="right_hit_sensor">
      <origin rpy="0 0 0" xyz="0 0 0"/>
      <geometry>
        <mesh filename="../meshes/hit_sensor.dae" scale="1.0 1.0 1.0"/>
      </geometry>
      <material name="hit_detector"/>
    </visual>
  </link>
  <link name="right_led_link">
    <inertial>
      <origin rpy="0 0 0" xyz="0 0 0"/>
      <mass value="0.001"/>
      <inertia ixx="0.001" ixy="0" ixz="0" iyy="0.001" iyz="0" izz="0.001"/>
    </inertial>
    <visual name="right_led">
      <origin rpy="0 0 0" xyz="0 0 0"/>
      <geometry>
        <mesh filename="../meshes/led.dae" scale="1.0 1.0 1.0"/>
      </geometry>
      <material name="led_light"/>
    </visual>
  </link>
  <joint name="right_hit_sensor_joint" type="fixed">
    <origin rpy="0 0 -1.5707963267948966" xyz="-0.0024413 -0.0886932 0.0298341"/>
    <parent link="chassis_base_link"/>
    <child link="right_hit_sensor_link"/>
  </joint>
  <joint name="right_led_joint" type="fixed">
    <origin rpy="0 0 0" xyz="0.0087428 -0.0012841 3.75e-05"/>
    <parent link="right_hit_sensor_link"/>
    <child link="right_led_link"/>
  </joint>

  

  <material name="armor_plastic">
    <color rgba="0.2277128 0.2277128 0.2277128 0.8"/>
  </material>
  <material name="chassis">
    <color rgba="0.0981132 0.0981132 0.0981132 1.0"/>
  </material>
  <material name="cover_plastic">
    <color rgba="0.2548322 0.2548322 0.2548322 0.30000000000000004"/>
  </material>
  <material name="dark_plastic">
    <color rgba="0.0281746 0.0281746 0.0281746 1.0"/>
  </material>
  <material name="metal">
    <color rgba="0.0281746 0.028 0.0281746 1.0"/>
  </material>
  <material name="hit_detector">
    <color rgba="0.1697846 0.1697846 0.1697846 1.0"/>
  </material>
  <material name="led_light">
    <color rgba="0 0.7773585 0.7773583 1.0"/>
  </material>
  <material name="wheel_plastic">
    <color rgba="0.2739087 0.2739087 0.2739087 1.0"/>
  </material>
  <material name="EP_up.001">
    <color rgba="0.0284811 0.0284811 0.0284811 1.0"/>
  </material>
  <link name="arm_1_link">
    <inertial>
      <origin rpy="0 0 0" xyz="-0.0005586 0.023592 0.0011729"/>
      <mass value="0.056"/>
      <inertia ixx="0.0156113" ixy="2.43e-05" ixz="1.8e-06" iyy="0.0161553" iyz="-0.0023011" izz="0.0018092"/>
    </inertial>
    <visual name="arm_1">
      <origin rpy="0 0 0" xyz="0.0073108 0.0184816 0.0437162"/>
      <geometry>
        <mesh filename="../meshes/arm_1.dae" scale="1.0 1.0 1.0"/>
      </geometry>
      <material name="metal"/>
    </visual>
    <visual name="arm_1_cylinder">
      <origin rpy="0 0 0" xyz="-0.0239031 0.0255713 -0.0368083"/>
      <geometry>
        <mesh filename="../meshes/arm_1_cylinder.dae" scale="1.0 1.0 1.0"/>
      </geometry>
      <material name="metal"/>
    </visual>
    <collision name="arm_1_collision">
      <origin rpy="0 0 0" xyz="0.0065116 0.0213649 0.0639448"/>
      <geometry>
        <mesh filename="../meshes/arm_1_collision.dae" scale="1.0 1.0 1.0"/>
      </geometry>
    </collision>
  </link>
  <!-- <link name="arm_2_dummy">
    </link> -->
  <link name="arm_2_link">
    <inertial>
      <origin rpy="0 0 0" xyz="0.0222614 -0.0202749 -0.008504"/>
      <mass value="0.08"/>
      <inertia ixx="0.0118624" ixy="1e-06" ixz="-3e-07" iyy="0.0041691" iyz="0.0031106" izz="0.0101456"/>
    </inertial>
    <visual name="arm_2">
      <origin rpy="0 0 0" xyz="0.0256122 -0.020134 -0.001308"/>
      <geometry>
        <mesh filename="../meshes/arm_2.dae" scale="1.0 1.0 1.0"/>
      </geometry>
      <material name="Test">
        <color rgba="0.0 0.0 0.0 1.0"/>
      </material>
    </visual>
    <visual name="arm_2_bar_1">
      <origin rpy="0 0 0" xyz="7.62e-05 0.0010863 -0.0002509"/>
      <geometry>
        <mesh filename="../meshes/arm_2_bar_1.dae" scale="1.0 1.0 1.0"/>
      </geometry>
      <material name="metal"/>
    </visual>
    <visual name="arm_2_bar_2">
      <origin rpy="0 0 0" xyz="-0.0423232 -0.0099192 0.0221971"/>
      <geometry>
        <mesh filename="../meshes/arm_2_bar_2.dae" scale="1.0 1.0 1.0"/>
      </geometry>
      <material name="metal"/>
    </visual>
    <collision name="arm_2_collision">
      <origin rpy="0 0 0" xyz="0.0222614 -0.0202749 -0.008504"/>
      <geometry>
        <mesh filename="../meshes/arm_2_collision.dae" scale="1.0 1.0 1.0"/>
      </geometry>
    </collision>
  </link>
  <!-- <link name="arm_base_attachment_link">
      <inertial>
        <origin xyz="0 0 0" rpy="0 0 0"/>
        <mass value="0.001"/>
        <inertia ixx="0.001" ixy="0" ixz="0" iyy="0.001" iyz="0" izz="0.001"/>
      </inertial>
    </link> -->
  <link name="arm_base_link">
    <inertial>
      <origin rpy="0 0 0" xyz="0 0 0"/>
      <mass value="0.3"/>
      <inertia ixx="0.0023" ixy="0" ixz="0" iyy="0.0025" iyz="0" izz="0.00072"/>
    </inertial>
    <visual name="arm_base">
      <origin rpy="0 0 0" xyz="-0.0008983 -0.0029745 -2.44e-05"/>
      <geometry>
        <mesh filename="../meshes/arm_base.dae" scale="1.0 1.0 1.0"/>
      </geometry>
      <material name="metal"/>
    </visual>
    <visual name="left_servo">
      <origin rpy="0 0 0" xyz="-0.013507 0 -0.0060673"/>
      <geometry>
        <mesh filename="../meshes/left_servo.dae" scale="1.0 1.0 1.0"/>
      </geometry>
      <material name="metal"/>
    </visual>
    <visual name="right_servo">
      <origin rpy="0 0 0" xyz="-0.013507 0 -0.0060673"/>
      <geometry>
        <mesh filename="../meshes/right_servo.dae" scale="1.0 1.0 1.0"/>
      </geometry>
      <material name="metal"/>
    </visual>
    <collision name="arm_base_collision">
      <origin rpy="0 0 0" xyz="-0.002098 -0.0004909 0.0073523"/>
      <geometry>
        <mesh filename="../meshes/arm_base_collision.dae" scale="1.0 1.0 1.0"/>
      </geometry>
    </collision>
  </link>
  <link name="end_point_link">
    </link>
  <link name="endpoint_bracket_link">
    <inertial>
      <origin rpy="0 0 0" xyz="0.0116468 -0.0288044 0.0041342"/>
      <mass value="0.028"/>
      <inertia ixx="0.0004413" ixy="0.0001147" ixz="2.69e-05" iyy="0.0008301" iyz="-2.89e-05" izz="0.0008237"/>
    </inertial>
    <visual name="endpoint_bracket">
      <origin rpy="0 0 0" xyz="0.0071657 -0.0245846 0.0008407"/>
      <geometry>
        <mesh filename="../meshes/endpoint_bracket.dae" scale="1.0 1.0 1.0"/>
      </geometry>
      <material name="metal"/>
    </visual>
    <collision name="endpoint_bracket_collision">
      <origin rpy="0 0 0" xyz="0.0116468 -0.0288044 0.0041342"/>
      <geometry>
        <mesh filename="../meshes/endpoint_bracket_collision.dae" scale="1.0 1.0 1.0"/>
      </geometry>
    </collision>
  </link>
  <!-- <link name="rod_1_dummy">
    </link> -->
  <link name="rod_1_link">
    <inertial>
      <origin rpy="0 0 0" xyz="-0.0477809 0 0.0272644"/>
      <mass value="0.012"/>
      <inertia ixx="0.0016031" ixy="0" ixz="0" iyy="0.0004085" iyz="0.000657" izz="0.0011959"/>
    </inertial>
    <visual name="rod_1">
      <origin rpy="0 0 0" xyz="-0.0479737 0 0.0301898"/>
      <geometry>
        <mesh filename="../meshes/rod_1.dae" scale="1.0 1.0 1.0"/>
      </geometry>
      <material name="metal"/>
    </visual>
    <collision name="rod_1_collision">
      <origin rpy="0 0 0" xyz="-0.0477809 0 0.0272644"/>
      <geometry>
        <mesh filename="../meshes/rod_1_collision.dae" scale="1.0 1.0 1.0"/>
      </geometry>
    </collision>
  </link>
  <!-- <link name="rod_2_dummy">
      <inertial>
        <origin xyz="0 0 0" rpy="0 0 0"/>
        <mass value="0.001"/>
        <inertia ixx="0.001" ixy="0" ixz="0" iyy="0.001" iyz="0" izz="0.001"/>
      </inertial>
    </link> -->
  <link name="rod_2_link">
    <inertial>
      <origin rpy="0 0 0" xyz="0.0011528 0 0.0549123"/>
      <mass value="0.012"/>
      <inertia ixx="0.0016147" ixy="0" ixz="0" iyy="0.0015792" iyz="-3.39e-05" izz="3.69e-05"/>
    </inertial>
    <visual name="rod_2">
      <origin rpy="0 0 0" xyz="-0.0012722 0 0.0561361"/>
      <geometry>
        <mesh filename="../meshes/rod_2.dae" scale="1.0000004 1.0 0.9999998"/>
      </geometry>
      <material name="metal"/>
    </visual>
    <collision name="rod_2_collision">
      <origin rpy="0 0 0" xyz="0.0011528 0 0.0549123"/>
      <geometry>
        <mesh filename="../meshes/rod_2_collision.dae" scale="1.0000004 1.0 0.9999998"/>
      </geometry>
    </collision>
  </link>
  <!-- <link name="rod_3_dummy">
      <inertial>
        <origin xyz="0 0 0" rpy="0 0 0"/>
        <mass value="0.001"/>
        <inertia ixx="0.001" ixy="0" ixz="0" iyy="0.001" iyz="0" izz="0.001"/>
      </inertial>
    </link> -->
  <link name="rod_3_link">
    <inertial>
      <origin rpy="0 0 0" xyz="-0.0003574 9.5e-06 0.0001674"/>
      <mass value="0.012"/>
      <inertia ixx="0.0059201" ixy="0" ixz="0" iyy="0.005887" iyz="1.87e-05" izz="3.45e-05"/>
    </inertial>
    <visual name="rod_3">
      <origin rpy="0 0 0" xyz="-0.0017304 0 0.0633558"/>
      <geometry>
        <mesh filename="../meshes/rod_3.dae" scale="1.0 1.0 1.0"/>
      </geometry>
      <material name="metal"/>
    </visual>
    <collision name="rod_3_collision">
      <origin rpy="0 0 0" xyz="0.0004696 9.5e-06 0.0561803"/>
      <geometry>
        <mesh filename="../meshes/rod_3_collision.dae" scale="1.0 1.0 1.0"/>
      </geometry>
    </collision>
  </link>
  <link name="rod_link">
    <inertial>
      <origin rpy="0 0 0" xyz="-8.11e-05 0.0023793 8.58e-05"/>
      <mass value="0.011"/>
      <inertia ixx="0.0009103" ixy="0" ixz="0" iyy="0.0002029" iyz="0.0003431" izz="0.0007136"/>
    </inertial>
    <visual name="rod">
      <origin rpy="0 0 0" xyz="-0.0261857 0.0022566 0.0121229"/>
      <geometry>
        <mesh filename="../meshes/rod.dae" scale="1.0 1.0 1.0"/>
      </geometry>
      <material name="metal"/>
    </visual>
    <collision name="rod_collision">
      <origin rpy="0 0 0" xyz="-0.02432 0.0022871 0.0136485"/>
      <geometry>
        <mesh filename="../meshes/rod_collision.dae" scale="1.0 1.0 1.0"/>
      </geometry>
    </collision>
  </link>
  <!-- <link name="triangle_1_dummy">
      <inertial>
        <origin xyz="0 0 0" rpy="0 0 0"/>
        <mass value="0.001"/>
        <inertia ixx="0.001" ixy="0" ixz="0" iyy="0.001" iyz="0" izz="0.001"/>
      </inertial>
    </link> -->
  <!-- <link name="triangle_2_dummy">
    </link> -->
  <link name="triangle_link">
    <inertial>
      <origin rpy="0 0 0" xyz="0.1417841 0.0321051 -0.1257179"/>
      <mass value="0.009"/>
      <inertia ixx="0.0205056" ixy="0.0021202" ixz="-0.0023248" iyy="0.0097562" iyz="0.0101162" izz="0.0117256"/>
    </inertial>
    <visual name="triangle">
      <origin rpy="0 0 0" xyz="-0.0095953 0 0.0131247"/>
      <geometry>
        <mesh filename="../meshes/triangle.dae" scale="1.0 1.0 1.0"/>
      </geometry>
      <material name="metal"/>
    </visual>
    <collision name="triangle_collision">
      <origin rpy="0 0 0" xyz="-0.0091994 0 0.012377"/>
      <geometry>
        <mesh filename="../meshes/triangle_collision.dae" scale="1.0 1.0 1.0"/>
      </geometry>
    </collision>
  </link>
  <joint name="arm_1_joint" type="fixed">
    <origin rpy="0 1.3 0" xyz="0.0103961 -0.0255713 0.030741"/>
    <parent link="arm_base_link"/>
    <child link="arm_1_link"/>
    <axis xyz="0.0 1.0 0"/>
    <limit effort="1" lower="-0.274" upper="1.384" velocity="1"/>
  </joint>
  <!-- <joint name="arm_2_dummy" type="floating">
      <origin xyz="-0.0419304 0.0028425 0.0218356" rpy="0 0 0"/>
      <parent link="arm_2_link"/>
      <child link="arm_2_dummy"/>
    </joint> -->
  <joint name="arm_2_joint" type="fixed">
    <origin rpy="0 -0.5 0" xyz="0.0018704 0.0438659 0.1210238"/>
    <parent link="arm_1_link"/>
    <child link="arm_2_link"/>
    <axis xyz="0.0 1.0 0"/>
    <limit effort="1" velocity="1"/>
    <mimic joint="rod_3_joint" multiplier="-1.0" offset="0.0"/>
  </joint>
  <!-- <joint name="arm_base_attachment_joint" type="fixed">
      <origin xyz="0 0.0010384 0.0906477" rpy="0 0 0"/>
      <parent link="base_link"/>
      <child link="arm_base_attachment_link"/>
    </joint> -->
  <joint name="arm_base_joint" type="fixed">
    <origin rpy="0 0 0" xyz="0 0.0010384 0.0906477"/>
    <parent link="chassis_base_link"/>
    <child link="arm_base_link"/>
  </joint>
  <!-- <joint name="attachement_link" type="floating">
      <origin xyz="0 0 0" rpy="0 0 0"/>
      <parent link="arm_base_link"/>
      <child link="attachement_link"/>
    </joint> -->
  <joint name="end_point_joint" type="fixed">
    <origin rpy="0 0 0" xyz="0.0110125 -0.0270264 -0.0103816"/>
    <parent link="endpoint_bracket_link"/>
    <child link="end_point_link"/>
  </joint>
  <joint name="endpoint_bracket_joint" type="fixed">
    <origin rpy="0 0 0" xyz="0.1058557 0.006752 -0.0561093"/>
    <parent link="arm_2_link"/>
    <child link="endpoint_bracket_link"/>
    <axis xyz="0.0 1.0 0"/>
    <mimic joint="rod_joint" multiplier="-1.0" offset="0.0"/>
    <!-- <limit effort="0" velocity="0"/> -->
  </joint>
  <!-- <joint name="rod_1_dummy" type="floating">
      <origin xyz="-0.1048751 0 0.0582511" rpy="0 0 0"/>
      <parent link="rod_1_link"/>
      <child link="rod_1_dummy"/>
    </joint> -->
  <joint name="rod_1_joint" type="fixed">
    <origin rpy="0 -0.021293 0" xyz="0.0134583 -0.0540971 0.0213068"/>
    <parent link="endpoint_bracket_link"/>
    <child link="rod_1_link"/>
    <axis xyz="0.0 1.0 0"/>
    <mimic joint="rod_joint" multiplier="1.0" offset="0.0"/>
  </joint>
  <!-- <joint name="rod_2_dummy" type="floating">
      <origin xyz="0.0036225 0 0.1198535" rpy="0 0 0"/>
      <parent link="rod_2_link"/>
      <child link="rod_2_dummy"/>
    </joint> -->
  <joint name="rod_2_joint" type="fixed">
    <origin rpy="0 1.3 0" xyz="-0.0224276 -0.0290701 0.0554782"/>
    <parent link="arm_base_link"/>
    <child link="rod_2_link"/>
    <axis xyz="0.0 1.0 0"/>
    <mimic joint="arm_1_joint" multiplier="1.0" offset="0.0"/>
    <!-- <limit effort="0" velocity="0"/> -->
  </joint>
  <!-- <joint name="rod_3_dummy" type="floating">
      <origin xyz="0.0029281 -0.0007404 0.1193638" rpy="0 0 0"/>
      <parent link="rod_3_link"/>
      <child link="rod_3_dummy"/>
    </joint> -->
  <joint name="rod_3_joint" type="fixed">
    <origin rpy="0 0.5 0" xyz="-0.042397 0.0004533 0.0223131"/>
    <parent link="rod_link"/>
    <child link="rod_3_link"/>
    <axis xyz="0.0 1.0 0"/>
    <limit effort="1" lower="-0.34732" upper="1.21475" velocity="1"/>
  </joint>
  <joint name="rod_joint" type="fixed">
    <origin rpy="0 0.8 0" xyz="0.009805 0.0214241 0.0319234"/>
    <parent link="arm_base_link"/>
    <child link="rod_link"/>
    <axis xyz="0.0 1.0 0"/>
    <limit effort="1" lower="-0.79936" upper="1.73137" velocity="1"/>
  </joint>
  <!-- <joint name="triangle_1_dummy" type="floating">
      <origin xyz="-0.037193 0 0.0147539" rpy="0 0 0"/>
      <parent link="triangle_link"/>
      <child link="triangle_1_dummy"/>
    </joint>

    <joint name="triangle_2_dummy" type="floating">
      <origin xyz="0.0077464 6.66e-05 0.0235099" rpy="0 0 0"/>
      <parent link="triangle_link"/>
      <child link="triangle_2_dummy"/>
    </joint> -->
  <joint name="triangle_joint" type="fixed">
    <origin rpy="0 -1.1 0" xyz="0.0020224 -0.007103 0.1212334"/>
    <parent link="arm_1_link"/>
    <child link="triangle_link"/>
    <axis xyz="0.0 1.0 0"/>
    <mimic joint="arm_1_joint" multiplier="-1.0" offset="0.0"/>
  </joint>




  <link name="left_gripper_link_1">
    <inertial>
      <origin rpy="0 0 0" xyz="0 0 0"/>
      <mass value="0.001"/>
      <inertia ixx="0.001" ixy="0" ixz="0" iyy="0.001" iyz="0" izz="0.001"/>
    </inertial>
    <visual name="left_gripper_1">
      <origin rpy="0 0 0" xyz="-1.52e-05 8.12e-05 -2.25e-05"/>
      <geometry>
        <mesh filename="../meshes/gripper_left_1.dae" scale="1.0 1.0 1.0"/>
      </geometry>
      <material name="EP_up.001"/>
    </visual>
  </link>
  <link name="left_gripper_link_2">
    <inertial>
      <origin rpy="0 0 0" xyz="0 0 0"/>
      <mass value="0.001"/>
      <inertia ixx="0.001" ixy="0" ixz="0" iyy="0.001" iyz="0" izz="0.001"/>
    </inertial>
    <visual name="left_gripper_2">
      <origin rpy="0 0 0" xyz="0.0135565 -0.0033557 -2.25e-05"/>
      <geometry>
        <mesh filename="../meshes/gripper_left_2.dae" scale="1.0 1.0 1.0"/>
      </geometry>
      <material name="EP_up.001"/>
    </visual>
    <collision name="left_gripper_2_collision">
      <origin rpy="0 0 0" xyz="0.0136108 -0.003318 -0.0296613"/>
      <geometry>
        <mesh filename="../meshes/gripper_left_2_collision.dae" scale="1.0 1.0 1.0"/>
      </geometry>
    </collision>
  </link>
  <!-- <link name="left_gripper_link_3_dummy">
          <inertial>
            <origin xyz="0 0 0" rpy="0 0 0"/>
            <mass value="0.001"/>
            <inertia ixx="0.001" ixy="0" ixz="0" iyy="0.001" iyz="0" izz="0.001"/>
          </inertial>
        </link> -->
  <link name="left_gripper_link_4">
    <inertial>
      <origin rpy="0 0 0" xyz="0 0 0"/>
      <mass value="0.001"/>
      <inertia ixx="0.001" ixy="0" ixz="0" iyy="0.001" iyz="0" izz="0.001"/>
    </inertial>
    <visual name="left_gripper_4">
      <origin rpy="0 0 0" xyz="-4.74e-05 0.0001737 -1.67e-05"/>
      <geometry>
        <mesh filename="../meshes/gripper_left_4.dae" scale="1.0 1.0 1.0"/>
      </geometry>
      <material name="EP_up.001"/>
    </visual>
    <collision name="left_gripper_4_collision">
      <origin rpy="0 0 0" xyz="-7.56e-05 -2.97e-05 -0.0296554"/>
      <geometry>
        <mesh filename="../meshes/gripper_left_4_collision.dae" scale="1.0 1.0 1.0"/>
      </geometry>
    </collision>
  </link>
  <link name="left_gripper_link_5">
    <inertial>
      <origin rpy="0 0 0" xyz="0 0 0"/>
      <mass value="0.001"/>
      <inertia ixx="0.001" ixy="0" ixz="0" iyy="0.001" iyz="0" izz="0.001"/>
    </inertial>
    <visual name="left_gripper_5">
      <origin rpy="0 0 0" xyz="-7.26e-05 -1.8e-06 -1.83e-05"/>
      <geometry>
        <mesh filename="../meshes/gripper_left_5.dae" scale="1.0 1.0 1.0"/>
      </geometry>
      <material name="EP_up.001"/>
    </visual>
    <collision name="left_gripper_5_collision">
      <origin rpy="0 0 0" xyz="-7.26e-05 -1.8e-06 -1.83e-05"/>
      <geometry>
        <mesh filename="../meshes/gripper_left_5_collision.dae" scale="1.0 1.0 1.0"/>
      </geometry>
    </collision>
  </link>
  <link name="left_gripper_link_6">
    <inertial>
      <origin rpy="0 0 0" xyz="0 0 0"/>
      <mass value="0.001"/>
      <inertia ixx="0.001" ixy="0" ixz="0" iyy="0.001" iyz="0" izz="0.001"/>
    </inertial>
    <visual name="left_gripper_6">
      <origin rpy="0 0 0" xyz="-0.0149194 -0.0168522 -1.83e-05"/>
      <geometry>
        <mesh filename="../meshes/gripper_left_6.dae" scale="1.0 1.0 1.0"/>
      </geometry>
      <material name="EP_up.001"/>
    </visual>
    <collision name="left_gripper_6_collision">
      <origin rpy="0 0 0" xyz="-0.0149892 -0.0167532 -0.0001821"/>
      <geometry>
        <mesh filename="../meshes/gripper_left_6_collision.dae" scale="1.0 1.0 1.0"/>
      </geometry>
    </collision>
  </link>
  <link name="left_gripper_link_7">
    <inertial>
      <origin rpy="0 0 0" xyz="0 0 0"/>
      <mass value="0.001"/>
      <inertia ixx="0.001" ixy="0" ixz="0" iyy="0.001" iyz="0" izz="0.001"/>
    </inertial>
    <visual name="left_gripper_7">
      <origin rpy="0 0 0" xyz="-0.0153264 -0.0166317 -1.83e-05"/>
      <geometry>
        <mesh filename="../meshes/gripper_left_7.dae" scale="1.0 1.0 1.0"/>
      </geometry>
      <material name="EP_up.001"/>
    </visual>
    <collision name="left_gripper_collision">
      <origin rpy="0 0 0" xyz="-0.0149126 -0.0167727 -0.0296388"/>
      <geometry>
        <mesh filename="../meshes/gripper_left_collision.dae" scale="1.0 1.0 1.0"/>
      </geometry>
    </collision>
  </link>
  <link name="gripper_link">
    <inertial>
      <origin rpy="0 0 0" xyz="0.0326578 -9.78e-05 -0.0327003"/>
      <mass value="0.15"/>
      <inertia ixx="0.0001376" ixy="7.89e-05" ixz="1.5e-06" iyy="0.0002582" iyz="2.9e-06" izz="0.0002497"/>
    </inertial>
    <visual name="gripper_base">
      <origin rpy="0 0 0" xyz="0 0 0"/>
      <geometry>
        <mesh filename="../meshes/gripper_base.dae" scale="1.0 1.0 1.0"/>
      </geometry>
      <material name="EP_up.001"/>
    </visual>
    <collision name="gripper_base_collision">
      <origin rpy="0 0 0" xyz="0.0003688 -9.78e-05 -0.0112797"/>
      <geometry>
        <mesh filename="../meshes/gripper_base_collision.dae" scale="1.0 1.0 1.0"/>
      </geometry>
    </collision>
  </link>
  <link name="gripper_m_link">
    <inertial>
      <origin rpy="0 0 0" xyz="0.0326578 -9.78e-05 -0.0327003"/>
      <mass value="0.15"/>
      <inertia ixx="0.0001376" ixy="7.89e-05" ixz="1.5e-06" iyy="0.0002582" iyz="2.9e-06" izz="0.0002497"/>
    </inertial>
  </link>
  <link name="gripper_t_link">

      </link>
  <joint name="gripper_m_joint" type="fixed">
    <limit effort="10000" lower="-0.023" upper="0.001" velocity="1"/>
    <origin rpy="0 0 0" xyz="0 0 0"/>
    <parent link="gripper_link"/>
    <child link="gripper_m_link"/>
    <axis xyz="-1 0 0"/>
  </joint>
  <!-- <link name="left_gripper_8_link_dummy">
          <inertial>
            <origin xyz="0 0 0" rpy="0 0 0"/>
            <mass value="0.001"/>
            <inertia ixx="0.001" ixy="0" ixz="0" iyy="0.001" iyz="0" izz="0.001"/>
          </inertial>
        </link> -->
  <link name="right_gripper_link_1">
    <inertial>
      <origin rpy="0 0 0" xyz="0 0 0"/>
      <mass value="0.001"/>
      <inertia ixx="0.001" ixy="0" ixz="0" iyy="0.001" iyz="0" izz="0.001"/>
    </inertial>
    <visual name="right_gripper_1">
      <origin rpy="0 0 0" xyz="-1.52e-05 -8.12e-05 -2.25e-05"/>
      <geometry>
        <mesh filename="../meshes/right_gripper_1.dae" scale="1.0 1.0 1.0"/>
      </geometry>
      <material name="EP_up.001"/>
    </visual>
  </link>
  <link name="right_gripper_link_2">
    <inertial>
      <origin rpy="0 0 0" xyz="0 0 0"/>
      <mass value="0.001"/>
      <inertia ixx="0.001" ixy="0" ixz="0" iyy="0.001" iyz="0" izz="0.001"/>
    </inertial>
    <visual name="right_gripper_2">
      <origin rpy="0 0 0" xyz="0.0127099 0.0021056 -2.25e-05"/>
      <geometry>
        <mesh filename="../meshes/right_gripper_2.dae" scale="1.0 1.0 1.0"/>
      </geometry>
      <material name="EP_up.001"/>
    </visual>
    <collision name="right_gripper_2_collision">
      <origin rpy="0 0 0" xyz="0.0134077 0.0024401 -0.0296613"/>
      <geometry>
        <mesh filename="../meshes/right_gripper_2_collision.dae" scale="1.0 1.0 1.0"/>
      </geometry>
    </collision>
  </link>
  <!-- <link name="right_gripper_link_3_dummy">
          <inertial>
            <origin xyz="0 0 0" rpy="0 0 0"/>
            <mass value="0.001"/>
            <inertia ixx="0.001" ixy="0" ixz="0" iyy="0.001" iyz="0" izz="0.001"/>
          </inertial>
        </link> -->
  <link name="right_gripper_link_4">
    <inertial>
      <origin rpy="0 0 0" xyz="0 0 0"/>
      <mass value="0.001"/>
      <inertia ixx="0.001" ixy="0" ixz="0" iyy="0.001" iyz="0" izz="0.001"/>
    </inertial>
    <visual name="right_gripper_4">
      <origin rpy="0 0 0" xyz="-4.74e-05 -0.0001737 -1.67e-05"/>
      <geometry>
        <mesh filename="../meshes/right_gripper_4.dae" scale="1.0 1.0 1.0"/>
      </geometry>
      <material name="EP_up.001"/>
    </visual>
    <collision name="right_gripper_4_collision">
      <origin rpy="0 0 0" xyz="-6.57e-05 1.16e-05 -0.0296554"/>
      <geometry>
        <mesh filename="../meshes/right_gripper_4_collision.dae" scale="1.0 1.0 1.0"/>
      </geometry>
    </collision>
  </link>
  <link name="right_gripper_link_5">
    <inertial>
      <origin rpy="0 0 0" xyz="0 0 0"/>
      <mass value="0.001"/>
      <inertia ixx="0.001" ixy="0" ixz="0" iyy="0.001" iyz="0" izz="0.001"/>
    </inertial>
    <visual name="right_gripper_5">
      <origin rpy="0 0 0" xyz="-7.26e-05 1.7e-06 -1.83e-05"/>
      <geometry>
        <mesh filename="../meshes/right_gripper_5.dae" scale="1.0 1.0 1.0"/>
      </geometry>
      <material name="EP_up.001"/>
    </visual>
    <collision name="right_gripper_5_collision">
      <origin rpy="0 0 0" xyz="-0.0001606 2.35e-05 8.1e-05"/>
      <geometry>
        <mesh filename="../meshes/right_gripper_5_collision.dae" scale="1.0 1.0 1.0"/>
      </geometry>
    </collision>
  </link>
  <link name="right_gripper_link_6">
    <inertial>
      <origin rpy="0 0 0" xyz="0 0 0"/>
      <mass value="0.001"/>
      <inertia ixx="0.001" ixy="0" ixz="0" iyy="0.001" iyz="0" izz="0.001"/>
    </inertial>
    <visual name="right_gripper_6">
      <origin rpy="0 0 0" xyz="-0.03103 0.0338258 -1.83e-05"/>
      <geometry>
        <mesh filename="../meshes/right_gripper_6.dae" scale="1.0 1.0 1.0"/>
      </geometry>
      <material name="EP_up.001"/>
    </visual>
    <collision name="right_gripper_6_collision">
      <origin rpy="0 0 0" xyz="-0.0156676 0.0173828 6.82e-05"/>
      <geometry>
        <mesh filename="../meshes/right_gripper_6_collision.dae" scale="1.0 1.0 1.0"/>
      </geometry>
    </collision>
  </link>
  <link name="right_gripper_link_7">
    <inertial>
      <origin rpy="0 0 0" xyz="0 0 0"/>
      <mass value="0.001"/>
      <inertia ixx="0.001" ixy="0" ixz="0" iyy="0.001" iyz="0" izz="0.001"/>
    </inertial>
    <visual name="right_gripper_7">
      <origin rpy="0 0 0" xyz="-3.72e-05 9e-07 -1.83e-05"/>
      <geometry>
        <mesh filename="../meshes/right_gripper_7.dae" scale="1.0 1.0 1.0"/>
      </geometry>
      <material name="EP_up.001"/>
    </visual>
    <collision name="right_gripper_7_collision">
      <origin rpy="0 0 0" xyz="-0.0150056 0.0168496 -0.0296388"/>
      <geometry>
        <mesh filename="../meshes/right_gripper_7_collision.dae" scale="1.0 1.0 1.0"/>
      </geometry>
    </collision>
  </link>
  <!-- <link name="right_gripper_link_8_dummy">
          <inertial>
            <origin xyz="0 0 0" rpy="0 0 0"/>
            <mass value="0.001"/>
            <inertia ixx="0.001" ixy="0" ixz="0" iyy="0.001" iyz="0" izz="0.001"/>
          </inertial>
        </link> -->
  <joint name="left_gripper_joint_1" type="revolute">
    <origin rpy="0 0 0" xyz="0.0163032 0.0212032 -0.0399201"/>
    <parent link="gripper_m_link"/>
    <child link="left_gripper_link_1"/>
    <axis xyz="0 0 1.0"/>
    <limit effort="10" lower="-0.4" upper="0" velocity="5"/>
  </joint>
  <joint name="left_gripper_joint_2" type="fixed">
    <origin rpy="0 0 0" xyz="0.0213495 0.0130363 0"/>
    <parent link="left_gripper_link_1"/>
    <child link="left_gripper_link_2"/>
    <axis xyz="0 0 1.0"/>
    <limit effort="1" velocity="1"/>
  </joint>
  <!-- <joint name="left_gripper_joint_3_dummy" type="fixed">
          <origin xyz="0.0136876 -0.0029412 0.0002778" rpy="0 0 0"/>
          <parent link="left_gripper_link_2"/>
          <child link="left_gripper_link_3_dummy"/>
        </joint> -->
  <joint name="left_gripper_joint_4" type="fixed">
    <origin rpy="0 0 0" xyz="0.00485 0.0204148 -5.8e-06"/>
    <parent link="left_gripper_link_2"/>
    <child link="left_gripper_link_4"/>
    <axis xyz="0 0 1.0"/>
    <limit effort="1" velocity="1"/>
  </joint>
  <joint name="left_gripper_joint_6" type="fixed">
    <origin rpy="0 0 0" xyz="0.0051144 -0.0140851 0"/>
    <parent link="left_gripper_link_5"/>
    <child link="left_gripper_link_6"/>
    <axis xyz="0 0 1.0"/>
    <limit effort="1" velocity="1"/>
  </joint>
  <joint name="left_gripper_joint_7" type="fixed">
    <origin rpy="0 0 0" xyz="-0.0148823 -0.0168513 0"/>
    <parent link="left_gripper_link_6"/>
    <child link="left_gripper_link_7"/>
    <axis xyz="0 0 1.0"/>
    <limit effort="1" velocity="1"/>
  </joint>
  <!-- <joint name="left_gripper_joint_8_dummy" type="fixed">
          <origin xyz="-0.014742 -0.0167196 -3.77e-05" rpy="0 0 0"/>
          <parent link="left_gripper_link_7"/>
          <child link="left_gripper_8_link_dummy"/>
        </joint> -->
  <joint name="left_gripper_joint_5" type="fixed">
    <origin rpy="0 0 0" xyz="0.0385916 0.0103143 1.6e-06"/>
    <parent link="left_gripper_link_4"/>
    <child link="left_gripper_link_5"/>
    <axis xyz="0 0 1.0"/>
    <limit effort="1" velocity="1"/>
  </joint>
  <joint name="gripper_joint" type="fixed">
    <origin rpy="0 -0.8 0" xyz="0.0002793 -0.027026 0.0001815"/>
    <parent link="endpoint_bracket_link"/>
    <child link="gripper_link"/>
  </joint>
  <joint name="right_gripper_joint_1" type="revolute">
    <origin rpy="0 0 0" xyz="0.0163034 -0.0209781 -0.0399201"/>
    <parent link="gripper_m_link"/>
    <child link="right_gripper_link_1"/>
    <axis xyz="0 0 1.0"/>
    <limit effort="10" lower="0" upper="0.4" velocity="5"/>
  </joint>
  <joint name="right_gripper_joint_2" type="fixed">
    <origin rpy="0 0 0" xyz="0.0213495 -0.0130363 0"/>
    <parent link="right_gripper_link_1"/>
    <child link="right_gripper_link_2"/>
    <axis xyz="0 0 1.0"/>
    <limit effort="1" velocity="1"/>
  </joint>
  <!-- <joint name="right_gripper_joint_3_dummy" type="fixed">
          <origin xyz="0.013553 0.0025081 0.0002778" rpy="0 0 0"/>
          <parent link="right_gripper_link_2"/>
          <child link="right_gripper_link_3_dummy"/>
        </joint> -->
  <joint name="right_gripper_joint_4" type="fixed">
    <origin rpy="0 0 0" xyz="0.0047151 -0.0208481 -5.8e-06"/>
    <parent link="right_gripper_link_2"/>
    <child link="right_gripper_link_4"/>
    <axis xyz="0 0 1.0"/>
    <limit effort="1" velocity="1"/>
  </joint>
  <joint name="right_gripper_joint_5" type="fixed">
    <origin rpy="0 0 0" xyz="0.0385916 -0.0103143 1.6e-06"/>
    <parent link="right_gripper_link_4"/>
    <child link="right_gripper_link_5"/>
    <axis xyz="0 0 1.0"/>
    <limit effort="1" velocity="1"/>
  </joint>
  <joint name="right_gripper_joint_6" type="fixed">
    <origin rpy="0 0 0" xyz="0.0059278 0.0133069 0"/>
    <parent link="right_gripper_link_5"/>
    <child link="right_gripper_link_6"/>
    <axis xyz="0 0 1.0"/>
    <limit effort="1" velocity="1"/>
  </joint>
  <joint name="right_gripper_joint_7" type="fixed">
    <origin rpy="0 0 0" xyz="-0.0156955 0.0176295 0"/>
    <parent link="right_gripper_link_6"/>
    <child link="right_gripper_link_7"/>
    <axis xyz="0 0 1.0"/>
    <limit effort="1" velocity="1"/>
  </joint>
  <joint name="gripper_joint_t" type="fixed">
    <origin rpy="0 0 0" xyz="0.124 0 -0.039"/>
    <parent link="gripper_link"/>
    <child link="gripper_t_link"/>
  </joint>




   <!-- <link name="front_left_wheel_link">
    <inertial>
      <origin rpy="0 0 0" xyz="-0.0002104 5.31e-05 -0.0004148"/>
      <mass value="0.162"/>
      <inertia ixx="0.0002" ixy="0" ixz="0" iyy="0.00012" iyz="0" izz="0.00012"/>
    </inertial>
    <visual name="front_left_wheel_bolt">
      <origin rpy="0 0 0" xyz="0 0.0145 0"/>
      <geometry>
        <cylinder length="0.001" radius="0.007"/>
      </geometry>
      <material name="bolt">
        <color rgba="0.45 0.15 0.0 1.0"/>
      </material>
    </visual>
    <visual name="front_left_wheel">
      <origin rpy="0 0 1.5707963267948966" xyz="0 0 0"/>
      <geometry>
        <mesh filename="../meshes/mecanum_wheel.dae" scale="0.6 0.6 0.6"/>
      </geometry>
      <material name="wheel_plastic"/>
    </visual>
    <collision name="front_left_wheel">
      <origin rpy="0 0 1.5707963267948966" xyz="0 0 0"/>
      <geometry>
        <mesh filename="../meshes/mecanum_wheel.stl" scale="0.6 0.6 0.6"/>
      </geometry>
      <material name="collision">
        <color rgba="0.8 0.0 0.0 1.0"/>
      </material>
    </collision>
  </link>  

  

  <link name="front_right_wheel_link">
    <inertial>
      <origin rpy="0 0 0" xyz="-0.0002104 5.31e-05 -0.0004148"/>
      <mass value="0.162"/>
      <inertia ixx="0.0002" ixy="0" ixz="0" iyy="0.00012" iyz="0" izz="0.00012"/>
    </inertial>
    <visual name="front_right_wheel_bolt">
      <origin rpy="1.5707963267948966 0 0" xyz="0 -0.0145 0"/>
      <geometry>
        <cylinder length="0.001" radius="0.007"/>
      </geometry>
      <material name="bolt">
        <color rgba="0.45 0.15 0.0 1.0"/>
      </material>
    </visual>
    <visual name="front_right_wheel">
      <origin rpy="0 0 1.5707963267948966" xyz="0 0 0"/>
      <geometry>
        <mesh filename="../meshes/mecanum_wheel.dae" scale="0.6 0.6 0.6"/>
      </geometry>
      <material name="wheel_plastic"/>
    </visual>
    <collision name="front_right_wheel">
      <origin rpy="0 0 1.5707963267948966" xyz="0 0 0"/>
      <geometry>
        <mesh filename="../meshes/mecanum_wheel.stl" scale="0.6 0.6 0.6"/>
      </geometry>
      <material name="collision">
        <color rgba="0.8 0.0 0.0 1.0"/>
      </material>
    </collision>
  </link>


  <link name="rear_left_wheel_link">
    <inertial>
      <origin rpy="0 0 0" xyz="-0.0002104 5.31e-05 -0.0004148"/>
      <mass value="0.162"/>
      <inertia ixx="0.0002" ixy="0" ixz="0" iyy="0.00012" iyz="0" izz="0.00012"/>
    </inertial>
    <visual name="rear_left_wheel_bolt">
      <origin rpy="1.5707963267948966 0 0" xyz="0 0.0145 0"/>
      <geometry>
        <cylinder length="0.001" radius="0.007"/>
      </geometry>
      <material name="bolt">
        <color rgba="0.45 0.15 0.0 1.0"/>
      </material>
    </visual>
    <visual name="rear_left_wheel">
      <origin rpy="0 0 1.5707963267948966" xyz="0 0 0"/>
      <geometry>
        <mesh filename="../meshes/mecanum_wheel.dae" scale="0.6 0.6 0.6"/>
      </geometry>
      <material name="wheel_plastic"/>
    </visual>
    <collision name="rear_left_wheel">
      <origin rpy="0 0 1.5707963267948966" xyz="0 0 0"/>
      <geometry>
        <mesh filename="../meshes/mecanum_wheel.stl" scale="0.6 0.6 0.6"/>
      </geometry>
      <material name="collision">
        <color rgba="0.8 0.0 0.0 1.0"/>
      </material>
    </collision>
  </link>
  

  <link name="rear_right_wheel_link">
    <inertial>
      <origin rpy="0 0 0" xyz="-0.0002104 5.31e-05 -0.0004148"/>
      <mass value="0.162"/>
      <inertia ixx="0.0002" ixy="0" ixz="0" iyy="0.00012" iyz="0" izz="0.00012"/>
    </inertial>
    <visual name="rear_right_wheel_bolt">
      <origin rpy="1.5707963267948966 0 0" xyz="0 -0.0145 0"/>
      <geometry>
        <cylinder length="0.001" radius="0.007"/>
      </geometry>
      <material name="bolt">
        <color rgba="0.45 0.15 0.0 1.0"/>
      </material>
    </visual>
    <visual name="rear_right_wheel">
      <origin rpy="0 0 1.5707963267948966" xyz="0 0 0"/>
      <geometry>
        <mesh filename="../meshes/mecanum_wheel.dae" scale="0.6 0.6 0.6"/>
      </geometry>
      <material name="wheel_plastic"/>
    </visual>
    <collision name="rear_right_wheel">
      <origin rpy="0 0 1.5707963267948966" xyz="0 0 0"/>
      <geometry>
        <mesh filename="../meshes/mecanum_wheel.stl" scale="0.6 0.6 0.6"/>
      </geometry>
      <material name="collision">
        <color rgba="0.8 0.0 0.0 1.0"/>
      </material>
    </collision>
  </link>-->



  <joint name="front_left_wheel_joint" type="continuous">
    <origin rpy="0 0 1.5707963267948966" xyz="0.1 0.1 0.01535"/>
    <parent link="chassis_base_link"/>
    <child link="front_left_wheel_link"/>
    <axis xyz="1 0 0"/>
  </joint>
  <joint name="front_right_wheel_joint" type="continuous">
    <origin rpy="0 0 1.5707963267948966" xyz="0.1 -0.1 0.01535"/>
    <parent link="chassis_base_link"/>
    <child link="front_right_wheel_link"/>
    <axis xyz="1 0 0"/>
  </joint>
  <joint name="rear_left_wheel_joint" type="continuous">
    <origin rpy="0 0 1.5707963267948966" xyz="-0.1 0.1 0.01535"/>
    <parent link="chassis_base_link"/>
    <child link="rear_left_wheel_link"/>
    <axis xyz="1 0 0"/>
  </joint>
  <joint name="rear_right_wheel_joint" type="continuous">
    <origin rpy="0 0 1.5707963267948966" xyz="-0.1 -0.1 0.01535"/>
    <parent link="chassis_base_link"/>
    <child link="rear_right_wheel_link"/>
    <axis xyz="1 0 0"/>
  </joint>




  


<link name="front_left_wheel_link">
    <visual>
      <origin rpy="0 0 0" xyz="0 0 0"/>
      <geometry>
        <mesh filename="../meshes/mecanum_wheel.dae" scale="0.6 0.6 0.6"/>
      </geometry>
    </visual>
    <collision>
      <origin rpy="0 0 0" xyz="0 0 0"/>
      <geometry>
        <mesh filename="../meshes/mecanum_wheel.stl" scale="0.6 0.6 0.6"/>
      </geometry>
    </collision>
    <inertial>
      <origin xyz="0 0 0" />
      <mass value="2.0"/>
      <inertia ixx="0.042025" ixy="0.0" ixz="0.0" iyy="0.024279" iyz="0.0" izz="0.024279"/>
    </inertial>
  </link>
  <link name="front_left_roller15_link">
    <visual>
      <origin rpy="0 0 0" xyz="0 0 0"/>
      <geometry>
        <mesh filename="../meshes/mecanum_roller.dae" scale="0.6 0.6 0.6"/>
      </geometry>
    </visual>
    <collision>
      <geometry>
        <mesh filename="../meshes/mecanum_roller.stl" scale="0.6 0.6 0.6"/>
      </geometry>
    </collision>
    <inertial>
      <origin xyz="0 0 0"/>
      <mass value="0.3"/>
      <inertia ixx="0.00024000" ixy="0.0" ixz="0.0" iyy="0.00076000" iyz="0.0" izz="0.00076000"/>
    </inertial>
  </link>
  <joint name="front_left_roller15_joint" type="continuous">
    <origin rpy="0.5619350361043127 -0.7022987807291682 0.38630030387691144" xyz="0 0.04905739107540767 -0.021841757733170465"/>
    <axis xyz="1 0 0"/>
    <parent link="front_left_wheel_link"/>
    <child link="front_left_roller15_link"/>
    <dynamics damping="0.001" friction="0.0001"/>
  </joint>
  <link name="front_left_roller14_link">
    <visual>
      <origin rpy="0 0 0" xyz="0 0 0"/>
      <geometry>
        <mesh filename="../meshes/mecanum_roller.dae" scale="0.6 0.6 0.6"/>
      </geometry>
    </visual>
    <collision>
      <geometry>
        <mesh filename="../meshes/mecanum_roller.stl" scale="0.6 0.6 0.6"/>
      </geometry>
    </collision>
    <inertial>
      <origin xyz="0 0 0"/>
      <mass value="0.3"/>
      <inertia ixx="0.00024000" ixy="0.0" ixz="0.0" iyy="0.00076000" iyz="0.0" izz="0.00076000"/>
    </inertial>
  </link>
  <joint name="front_left_roller14_joint" type="continuous">
    <origin rpy="1.0038406803226874 -0.4928592704898482 0.6390993414905143" xyz="0 0.03593231356147066 -0.039906877128136085"/>
    <axis xyz="1 0 0"/>
    <parent link="front_left_wheel_link"/>
    <child link="front_left_roller14_link"/>
    <dynamics damping="0.001" friction="0.0001"/>
  </joint>
  <link name="front_left_roller13_link">
    <visual>
      <origin rpy="0 0 0" xyz="0 0 0"/>
      <geometry>
        <mesh filename="../meshes/mecanum_roller.dae" scale="0.6 0.6 0.6"/>
      </geometry>
    </visual>
    <collision>
      <geometry>
        <mesh filename="../meshes/mecanum_roller.stl" scale="0.6 0.6 0.6"/>
      </geometry>
    </collision>
    <inertial>
      <origin xyz="0 0 0"/>
      <mass value="0.3"/>
      <inertia ixx="0.00024000" ixy="0.0" ixz="0.0" iyy="0.00076000" iyz="0.0" izz="0.00076000"/>
    </inertial>
  </link>
  <joint name="front_left_roller13_joint" type="continuous">
    <origin rpy="1.3449626171032882 -0.22028527385474703 0.7603177925108144" xyz="0 0.01659421259793466 -0.051071734925049746"/>
    <axis xyz="1 0 0"/>
    <parent link="front_left_wheel_link"/>
    <child link="front_left_roller13_link"/>
    <dynamics damping="0.001" friction="0.0001"/>
  </joint>
  <link name="front_left_roller12_link">
    <visual>
      <origin rpy="0 0 0" xyz="0 0 0"/>
      <geometry>
        <mesh filename="../meshes/mecanum_roller.dae" scale="0.6 0.6 0.6"/>
      </geometry>
    </visual>
    <collision>
      <geometry>
        <mesh filename="../meshes/mecanum_roller.stl" scale="0.6 0.6 0.6"/>
      </geometry>
    </collision>
    <inertial>
      <origin xyz="0 0 0"/>
      <mass value="0.3"/>
      <inertia ixx="0.00024000" ixy="0.0" ixz="0.0" iyy="0.00076000" iyz="0.0" izz="0.00076000"/>
    </inertial>
  </link>
  <joint name="front_left_roller12_joint" type="continuous">
    <origin rpy="-1.4966127917301506 0.07398025001120935 0.7826515949744619" xyz="0 -0.0056131784774729855 -0.05340582578127628"/>
    <axis xyz="1 0 0"/>
    <parent link="front_left_wheel_link"/>
    <child link="front_left_roller12_link"/>
    <dynamics damping="0.001" friction="0.0001"/>
  </joint>
  <link name="front_left_roller11_link">
    <visual>
      <origin rpy="0 0 0" xyz="0 0 0"/>
      <geometry>
        <mesh filename="../meshes/mecanum_roller.dae" scale="0.6 0.6 0.6"/>
      </geometry>
    </visual>
    <collision>
      <geometry>
        <mesh filename="../meshes/mecanum_roller.stl" scale="0.6 0.6 0.6"/>
      </geometry>
    </collision>
    <inertial>
      <origin xyz="0 0 0"/>
      <mass value="0.3"/>
      <inertia ixx="0.00024000" ixy="0.0" ixz="0.0" iyy="0.00076000" iyz="0.0" izz="0.00076000"/>
    </inertial>
  </link>
  <joint name="front_left_roller11_joint" type="continuous">
    <origin rpy="-1.1831996401397156 0.3613671239067081 0.7137243789447655" xyz="0 -0.026850000000000023 -0.04650556418322434"/>
    <axis xyz="1 0 0"/>
    <parent link="front_left_wheel_link"/>
    <child link="front_left_roller11_link"/>
    <dynamics damping="0.001" friction="0.0001"/>
  </joint>
  <link name="front_left_roller10_link">
    <visual>
      <origin rpy="0 0 0" xyz="0 0 0"/>
      <geometry>
        <mesh filename="../meshes/mecanum_roller.dae" scale="0.6 0.6 0.6"/>
      </geometry>
    </visual>
    <collision>
      <geometry>
        <mesh filename="../meshes/mecanum_roller.stl" scale="0.6 0.6 0.6"/>
      </geometry>
    </collision>
    <inertial>
      <origin xyz="0 0 0"/>
      <mass value="0.3"/>
      <inertia ixx="0.00024000" ixy="0.0" ixz="0.0" iyy="0.00076000" iyz="0.0" izz="0.00076000"/>
    </inertial>
  </link>
  <joint name="front_left_roller10_joint" type="continuous">
    <origin rpy="-0.7989541677433551 0.6090169187607924 0.5313896516603533" xyz="0 -0.04344421259793468 -0.0315640680481058"/>
    <axis xyz="1 0 0"/>
    <parent link="front_left_wheel_link"/>
    <child link="front_left_roller10_link"/>
    <dynamics damping="0.001" friction="0.0001"/>
  </joint>
  <link name="front_left_roller9_link">
    <visual>
      <origin rpy="0 0 0" xyz="0 0 0"/>
      <geometry>
        <mesh filename="../meshes/mecanum_roller.dae" scale="0.6 0.6 0.6"/>
      </geometry>
    </visual>
    <collision>
      <geometry>
        <mesh filename="../meshes/mecanum_roller.stl" scale="0.6 0.6 0.6"/>
      </geometry>
    </collision>
    <inertial>
      <origin xyz="0 0 0"/>
      <mass value="0.3"/>
      <inertia ixx="0.00024000" ixy="0.0" ixz="0.0" iyy="0.00076000" iyz="0.0" izz="0.00076000"/>
    </inertial>
  </link>
  <joint name="front_left_roller9_joint" type="continuous">
    <origin rpy="-0.29200750368454736 0.7637777909460687 0.20499125187874406" xyz="0 -0.052526526159405354 -0.011164857796913686"/>
    <axis xyz="1 0 0"/>
    <parent link="front_left_wheel_link"/>
    <child link="front_left_roller9_link"/>
    <dynamics damping="0.001" friction="0.0001"/>
  </joint>
  <link name="front_left_roller8_link">
    <visual>
      <origin rpy="0 0 0" xyz="0 0 0"/>
      <geometry>
        <mesh filename="../meshes/mecanum_roller.dae" scale="0.6 0.6 0.6"/>
      </geometry>
    </visual>
    <collision>
      <geometry>
        <mesh filename="../meshes/mecanum_roller.stl" scale="0.6 0.6 0.6"/>
      </geometry>
    </collision>
    <inertial>
      <origin xyz="0 0 0"/>
      <mass value="0.3"/>
      <inertia ixx="0.00024000" ixy="0.0" ixz="0.0" iyy="0.00076000" iyz="0.0" izz="0.00076000"/>
    </inertial>
  </link>
  <joint name="front_left_roller8_joint" type="continuous">
    <origin rpy="0.2920075036845471 0.7637777909460687 -0.20499125187874387" xyz="0 -0.05252652615940536 0.011164857796913676"/>
    <axis xyz="1 0 0"/>
    <parent link="front_left_wheel_link"/>
    <child link="front_left_roller8_link"/>
    <dynamics damping="0.001" friction="0.0001"/>
  </joint>
  <link name="front_left_roller7_link">
    <visual>
      <origin rpy="0 0 0" xyz="0 0 0"/>
      <geometry>
        <mesh filename="../meshes/mecanum_roller.dae" scale="0.6 0.6 0.6"/>
      </geometry>
    </visual>
    <collision>
      <geometry>
        <mesh filename="../meshes/mecanum_roller.stl" scale="0.6 0.6 0.6"/>
      </geometry>
    </collision>
    <inertial>
      <origin xyz="0 0 0"/>
      <mass value="0.3"/>
      <inertia ixx="0.00024000" ixy="0.0" ixz="0.0" iyy="0.00076000" iyz="0.0" izz="0.00076000"/>
    </inertial>
  </link>
  <joint name="front_left_roller7_joint" type="continuous">
    <origin rpy="0.7989541677433554 0.6090169187607923 -0.5313896516603536" xyz="0 -0.04344421259793467 0.03156406804810581"/>
    <axis xyz="1 0 0"/>
    <parent link="front_left_wheel_link"/>
    <child link="front_left_roller7_link"/>
    <dynamics damping="0.001" friction="0.0001"/>
  </joint>
  <link name="front_left_roller6_link">
    <visual>
      <origin rpy="0 0 0" xyz="0 0 0"/>
      <geometry>
        <mesh filename="../meshes/mecanum_roller.dae" scale="0.6 0.6 0.6"/>
      </geometry>
    </visual>
    <collision>
      <geometry>
        <mesh filename="../meshes/mecanum_roller.stl" scale="0.6 0.6 0.6"/>
      </geometry>
    </collision>
    <inertial>
      <origin xyz="0 0 0"/>
      <mass value="0.3"/>
      <inertia ixx="0.00024000" ixy="0.0" ixz="0.0" iyy="0.00076000" iyz="0.0" izz="0.00076000"/>
    </inertial>
  </link>
  <joint name="front_left_roller6_joint" type="continuous">
    <origin rpy="1.1831996401397162 0.3613671239067076 -0.7137243789447657" xyz="0 -0.026849999999999985 0.04650556418322435"/>
    <axis xyz="1 0 0"/>
    <parent link="front_left_wheel_link"/>
    <child link="front_left_roller6_link"/>
    <dynamics damping="0.001" friction="0.0001"/>
  </joint>
  <link name="front_left_roller5_link">
    <visual>
      <origin rpy="0 0 0" xyz="0 0 0"/>
      <geometry>
        <mesh filename="../meshes/mecanum_roller.dae" scale="0.6 0.6 0.6"/>
      </geometry>
    </visual>
    <collision>
      <geometry>
        <mesh filename="../meshes/mecanum_roller.stl" scale="0.6 0.6 0.6"/>
      </geometry>
    </collision>
    <inertial>
      <origin xyz="0 0 0"/>
      <mass value="0.3"/>
      <inertia ixx="0.00024000" ixy="0.0" ixz="0.0" iyy="0.00076000" iyz="0.0" izz="0.00076000"/>
    </inertial>
  </link>
  <joint name="front_left_roller5_joint" type="continuous">
    <origin rpy="1.4966127917301504 0.07398025001120949 -0.7826515949744619" xyz="0 -0.005613178477472996 0.05340582578127627"/>
    <axis xyz="1 0 0"/>
    <parent link="front_left_wheel_link"/>
    <child link="front_left_roller5_link"/>
    <dynamics damping="0.001" friction="0.0001"/>
  </joint>
  <link name="front_left_roller4_link">
    <visual>
      <origin rpy="0 0 0" xyz="0 0 0"/>
      <geometry>
        <mesh filename="../meshes/mecanum_roller.dae" scale="0.6 0.6 0.6"/>
      </geometry>
    </visual>
    <collision>
      <geometry>
        <mesh filename="../meshes/mecanum_roller.stl" scale="0.6 0.6 0.6"/>
      </geometry>
    </collision>
    <inertial>
      <origin xyz="0 0 0"/>
      <mass value="0.3"/>
      <inertia ixx="0.00024000" ixy="0.0" ixz="0.0" iyy="0.00076000" iyz="0.0" izz="0.00076000"/>
    </inertial>
  </link>
  <joint name="front_left_roller4_joint" type="continuous">
    <origin rpy="-1.3449626171032882 -0.2202852738547472 -0.7603177925108144" xyz="0 0.016594212597934678 0.051071734925049746"/>
    <axis xyz="1 0 0"/>
    <parent link="front_left_wheel_link"/>
    <child link="front_left_roller4_link"/>
    <dynamics damping="0.001" friction="0.0001"/>
  </joint>
  <link name="front_left_roller3_link">
    <visual>
      <origin rpy="0 0 0" xyz="0 0 0"/>
      <geometry>
        <mesh filename="../meshes/mecanum_roller.dae" scale="0.6 0.6 0.6"/>
      </geometry>
    </visual>
    <collision>
      <geometry>
        <mesh filename="../meshes/mecanum_roller.stl" scale="0.6 0.6 0.6"/>
      </geometry>
    </collision>
    <inertial>
      <origin xyz="0 0 0"/>
      <mass value="0.3"/>
      <inertia ixx="0.00024000" ixy="0.0" ixz="0.0" iyy="0.00076000" iyz="0.0" izz="0.00076000"/>
    </inertial>
  </link>
  <joint name="front_left_roller3_joint" type="continuous">
    <origin rpy="-1.0038406803226867 -0.4928592704898485 -0.6390993414905141" xyz="0 0.03593231356147068 0.03990687712813607"/>
    <axis xyz="1 0 0"/>
    <parent link="front_left_wheel_link"/>
    <child link="front_left_roller3_link"/>
    <dynamics damping="0.001" friction="0.0001"/>
  </joint>
  <link name="front_left_roller2_link">
    <visual>
      <origin rpy="0 0 0" xyz="0 0 0"/>
      <geometry>
        <mesh filename="../meshes/mecanum_roller.dae" scale="0.6 0.6 0.6"/>
      </geometry>
    </visual>
    <collision>
      <geometry>
        <mesh filename="../meshes/mecanum_roller.stl" scale="0.6 0.6 0.6"/>
      </geometry>
    </collision>
    <inertial>
      <origin xyz="0 0 0"/>
      <mass value="0.3"/>
      <inertia ixx="0.00024000" ixy="0.0" ixz="0.0" iyy="0.00076000" iyz="0.0" izz="0.00076000"/>
    </inertial>
  </link>
  <joint name="front_left_roller2_joint" type="continuous">
    <origin rpy="-0.5619350361043128 -0.702298780729168 -0.3863003038769115" xyz="0 0.049057391075407665 0.02184175773317047"/>
    <axis xyz="1 0 0"/>
    <parent link="front_left_wheel_link"/>
    <child link="front_left_roller2_link"/>
    <dynamics damping="0.001" friction="0.0001"/>
  </joint>
  <link name="front_left_roller1_link">
    <visual>
      <origin rpy="0 0 0" xyz="0 0 0"/>
      <geometry>
        <mesh filename="../meshes/mecanum_roller.dae" scale="0.6 0.6 0.6"/>
      </geometry>
    </visual>
    <collision>
      <geometry>
        <mesh filename="../meshes/mecanum_roller.stl" scale="0.6 0.6 0.6"/>
      </geometry>
    </collision>
    <inertial>
      <origin xyz="0 0 0"/>
      <mass value="0.3"/>
      <inertia ixx="0.00024000" ixy="0.0" ixz="0.0" iyy="0.00076000" iyz="0.0" izz="0.00076000"/>
    </inertial>
  </link>
  <joint name="front_left_roller1_joint" type="continuous">
    <origin rpy="-0.0 -0.7853981633974482 -0.0" xyz="0 0.0537 0.0"/>
    <axis xyz="1 0 0"/>
    <parent link="front_left_wheel_link"/>
    <child link="front_left_roller1_link"/>
    <dynamics damping="0.001" friction="0.0001"/>
  </joint>
  

<link name="front_right_wheel_link">
    <visual>
      <origin rpy="0 0 0" xyz="0 0 0"/>
      <geometry>
        <mesh filename="../meshes/mecanum_wheel.dae" scale="0.6 0.6 0.6"/>
      </geometry>
    </visual>
    <collision>
      <origin rpy="0 0 0" xyz="0 0 0"/>
      <geometry>
        <mesh filename="../meshes/mecanum_wheel.stl" scale="0.6 0.6 0.6"/>
      </geometry>
    </collision>
    <inertial>
      <origin xyz="0 0 0" />
      <mass value="2.0"/>
      <inertia ixx="0.042025" ixy="0.0" ixz="0.0" iyy="0.024279" iyz="0.0" izz="0.024279"/>
    </inertial>
  </link>
  <link name="front_right_roller15_link">
    <visual>
      <origin rpy="0 0 0" xyz="0 0 0"/>
      <geometry>
        <mesh filename="../meshes/mecanum_roller.dae" scale="0.6 0.6 0.6"/>
      </geometry>
    </visual>
    <collision>
      <geometry>
        <mesh filename="../meshes/mecanum_roller.stl" scale="0.6 0.6 0.6"/>
      </geometry>
    </collision>
    <inertial>
      <origin xyz="0 0 0"/>
      <mass value="0.3"/>
      <inertia ixx="0.00024000" ixy="0.0" ixz="0.0" iyy="0.00076000" iyz="0.0" izz="0.00076000"/>
    </inertial>
  </link>
  <joint name="front_right_roller15_joint" type="continuous">
    <origin rpy="0.5619350361043127 0.7022987807291682 -0.38630030387691144" xyz="0 0.04905739107540767 -0.021841757733170465"/>
    <axis xyz="1 0 0"/>
    <parent link="front_right_wheel_link"/>
    <child link="front_right_roller15_link"/>
    <dynamics damping="0.001" friction="0.0001"/>
  </joint>
  <link name="front_right_roller14_link">
    <visual>
      <origin rpy="0 0 0" xyz="0 0 0"/>
      <geometry>
        <mesh filename="../meshes/mecanum_roller.dae" scale="0.6 0.6 0.6"/>
      </geometry>
    </visual>
    <collision>
      <geometry>
        <mesh filename="../meshes/mecanum_roller.stl" scale="0.6 0.6 0.6"/>
      </geometry>
    </collision>
    <inertial>
      <origin xyz="0 0 0"/>
      <mass value="0.3"/>
      <inertia ixx="0.00024000" ixy="0.0" ixz="0.0" iyy="0.00076000" iyz="0.0" izz="0.00076000"/>
    </inertial>
  </link>
  <joint name="front_right_roller14_joint" type="continuous">
    <origin rpy="1.0038406803226874 0.4928592704898482 -0.6390993414905143" xyz="0 0.03593231356147066 -0.039906877128136085"/>
    <axis xyz="1 0 0"/>
    <parent link="front_right_wheel_link"/>
    <child link="front_right_roller14_link"/>
    <dynamics damping="0.001" friction="0.0001"/>
  </joint>
  <link name="front_right_roller13_link">
    <visual>
      <origin rpy="0 0 0" xyz="0 0 0"/>
      <geometry>
        <mesh filename="../meshes/mecanum_roller.dae" scale="0.6 0.6 0.6"/>
      </geometry>
    </visual>
    <collision>
      <geometry>
        <mesh filename="../meshes/mecanum_roller.stl" scale="0.6 0.6 0.6"/>
      </geometry>
    </collision>
    <inertial>
      <origin xyz="0 0 0"/>
      <mass value="0.3"/>
      <inertia ixx="0.00024000" ixy="0.0" ixz="0.0" iyy="0.00076000" iyz="0.0" izz="0.00076000"/>
    </inertial>
  </link>
  <joint name="front_right_roller13_joint" type="continuous">
    <origin rpy="1.3449626171032882 0.22028527385474703 -0.7603177925108144" xyz="0 0.01659421259793466 -0.051071734925049746"/>
    <axis xyz="1 0 0"/>
    <parent link="front_right_wheel_link"/>
    <child link="front_right_roller13_link"/>
    <dynamics damping="0.001" friction="0.0001"/>
  </joint>
  <link name="front_right_roller12_link">
    <visual>
      <origin rpy="0 0 0" xyz="0 0 0"/>
      <geometry>
        <mesh filename="../meshes/mecanum_roller.dae" scale="0.6 0.6 0.6"/>
      </geometry>
    </visual>
    <collision>
      <geometry>
        <mesh filename="../meshes/mecanum_roller.stl" scale="0.6 0.6 0.6"/>
      </geometry>
    </collision>
    <inertial>
      <origin xyz="0 0 0"/>
      <mass value="0.3"/>
      <inertia ixx="0.00024000" ixy="0.0" ixz="0.0" iyy="0.00076000" iyz="0.0" izz="0.00076000"/>
    </inertial>
  </link>
  <joint name="front_right_roller12_joint" type="continuous">
    <origin rpy="-1.4966127917301506 -0.07398025001120935 -0.7826515949744619" xyz="0 -0.0056131784774729855 -0.05340582578127628"/>
    <axis xyz="1 0 0"/>
    <parent link="front_right_wheel_link"/>
    <child link="front_right_roller12_link"/>
    <dynamics damping="0.001" friction="0.0001"/>
  </joint>
  <link name="front_right_roller11_link">
    <visual>
      <origin rpy="0 0 0" xyz="0 0 0"/>
      <geometry>
        <mesh filename="../meshes/mecanum_roller.dae" scale="0.6 0.6 0.6"/>
      </geometry>
    </visual>
    <collision>
      <geometry>
        <mesh filename="../meshes/mecanum_roller.stl" scale="0.6 0.6 0.6"/>
      </geometry>
    </collision>
    <inertial>
      <origin xyz="0 0 0"/>
      <mass value="0.3"/>
      <inertia ixx="0.00024000" ixy="0.0" ixz="0.0" iyy="0.00076000" iyz="0.0" izz="0.00076000"/>
    </inertial>
  </link>
  <joint name="front_right_roller11_joint" type="continuous">
    <origin rpy="-1.1831996401397156 -0.3613671239067081 -0.7137243789447655" xyz="0 -0.026850000000000023 -0.04650556418322434"/>
    <axis xyz="1 0 0"/>
    <parent link="front_right_wheel_link"/>
    <child link="front_right_roller11_link"/>
    <dynamics damping="0.001" friction="0.0001"/>
  </joint>
  <link name="front_right_roller10_link">
    <visual>
      <origin rpy="0 0 0" xyz="0 0 0"/>
      <geometry>
        <mesh filename="../meshes/mecanum_roller.dae" scale="0.6 0.6 0.6"/>
      </geometry>
    </visual>
    <collision>
      <geometry>
        <mesh filename="../meshes/mecanum_roller.stl" scale="0.6 0.6 0.6"/>
      </geometry>
    </collision>
    <inertial>
      <origin xyz="0 0 0"/>
      <mass value="0.3"/>
      <inertia ixx="0.00024000" ixy="0.0" ixz="0.0" iyy="0.00076000" iyz="0.0" izz="0.00076000"/>
    </inertial>
  </link>
  <joint name="front_right_roller10_joint" type="continuous">
    <origin rpy="-0.7989541677433551 -0.6090169187607924 -0.5313896516603533" xyz="0 -0.04344421259793468 -0.0315640680481058"/>
    <axis xyz="1 0 0"/>
    <parent link="front_right_wheel_link"/>
    <child link="front_right_roller10_link"/>
    <dynamics damping="0.001" friction="0.0001"/>
  </joint>
  <link name="front_right_roller9_link">
    <visual>
      <origin rpy="0 0 0" xyz="0 0 0"/>
      <geometry>
        <mesh filename="../meshes/mecanum_roller.dae" scale="0.6 0.6 0.6"/>
      </geometry>
    </visual>
    <collision>
      <geometry>
        <mesh filename="../meshes/mecanum_roller.stl" scale="0.6 0.6 0.6"/>
      </geometry>
    </collision>
    <inertial>
      <origin xyz="0 0 0"/>
      <mass value="0.3"/>
      <inertia ixx="0.00024000" ixy="0.0" ixz="0.0" iyy="0.00076000" iyz="0.0" izz="0.00076000"/>
    </inertial>
  </link>
  <joint name="front_right_roller9_joint" type="continuous">
    <origin rpy="-0.29200750368454736 -0.7637777909460687 -0.20499125187874406" xyz="0 -0.052526526159405354 -0.011164857796913686"/>
    <axis xyz="1 0 0"/>
    <parent link="front_right_wheel_link"/>
    <child link="front_right_roller9_link"/>
    <dynamics damping="0.001" friction="0.0001"/>
  </joint>
  <link name="front_right_roller8_link">
    <visual>
      <origin rpy="0 0 0" xyz="0 0 0"/>
      <geometry>
        <mesh filename="../meshes/mecanum_roller.dae" scale="0.6 0.6 0.6"/>
      </geometry>
    </visual>
    <collision>
      <geometry>
        <mesh filename="../meshes/mecanum_roller.stl" scale="0.6 0.6 0.6"/>
      </geometry>
    </collision>
    <inertial>
      <origin xyz="0 0 0"/>
      <mass value="0.3"/>
      <inertia ixx="0.00024000" ixy="0.0" ixz="0.0" iyy="0.00076000" iyz="0.0" izz="0.00076000"/>
    </inertial>
  </link>
  <joint name="front_right_roller8_joint" type="continuous">
    <origin rpy="0.2920075036845471 -0.7637777909460687 0.20499125187874387" xyz="0 -0.05252652615940536 0.011164857796913676"/>
    <axis xyz="1 0 0"/>
    <parent link="front_right_wheel_link"/>
    <child link="front_right_roller8_link"/>
    <dynamics damping="0.001" friction="0.0001"/>
  </joint>
  <link name="front_right_roller7_link">
    <visual>
      <origin rpy="0 0 0" xyz="0 0 0"/>
      <geometry>
        <mesh filename="../meshes/mecanum_roller.dae" scale="0.6 0.6 0.6"/>
      </geometry>
    </visual>
    <collision>
      <geometry>
        <mesh filename="../meshes/mecanum_roller.stl" scale="0.6 0.6 0.6"/>
      </geometry>
    </collision>
    <inertial>
      <origin xyz="0 0 0"/>
      <mass value="0.3"/>
      <inertia ixx="0.00024000" ixy="0.0" ixz="0.0" iyy="0.00076000" iyz="0.0" izz="0.00076000"/>
    </inertial>
  </link>
  <joint name="front_right_roller7_joint" type="continuous">
    <origin rpy="0.7989541677433554 -0.6090169187607923 0.5313896516603536" xyz="0 -0.04344421259793467 0.03156406804810581"/>
    <axis xyz="1 0 0"/>
    <parent link="front_right_wheel_link"/>
    <child link="front_right_roller7_link"/>
    <dynamics damping="0.001" friction="0.0001"/>
  </joint>
  <link name="front_right_roller6_link">
    <visual>
      <origin rpy="0 0 0" xyz="0 0 0"/>
      <geometry>
        <mesh filename="../meshes/mecanum_roller.dae" scale="0.6 0.6 0.6"/>
      </geometry>
    </visual>
    <collision>
      <geometry>
        <mesh filename="../meshes/mecanum_roller.stl" scale="0.6 0.6 0.6"/>
      </geometry>
    </collision>
    <inertial>
      <origin xyz="0 0 0"/>
      <mass value="0.3"/>
      <inertia ixx="0.00024000" ixy="0.0" ixz="0.0" iyy="0.00076000" iyz="0.0" izz="0.00076000"/>
    </inertial>
  </link>
  <joint name="front_right_roller6_joint" type="continuous">
    <origin rpy="1.1831996401397162 -0.3613671239067076 0.7137243789447657" xyz="0 -0.026849999999999985 0.04650556418322435"/>
    <axis xyz="1 0 0"/>
    <parent link="front_right_wheel_link"/>
    <child link="front_right_roller6_link"/>
    <dynamics damping="0.001" friction="0.0001"/>
  </joint>
  <link name="front_right_roller5_link">
    <visual>
      <origin rpy="0 0 0" xyz="0 0 0"/>
      <geometry>
        <mesh filename="../meshes/mecanum_roller.dae" scale="0.6 0.6 0.6"/>
      </geometry>
    </visual>
    <collision>
      <geometry>
        <mesh filename="../meshes/mecanum_roller.stl" scale="0.6 0.6 0.6"/>
      </geometry>
    </collision>
    <inertial>
      <origin xyz="0 0 0"/>
      <mass value="0.3"/>
      <inertia ixx="0.00024000" ixy="0.0" ixz="0.0" iyy="0.00076000" iyz="0.0" izz="0.00076000"/>
    </inertial>
  </link>
  <joint name="front_right_roller5_joint" type="continuous">
    <origin rpy="1.4966127917301504 -0.07398025001120949 0.7826515949744619" xyz="0 -0.005613178477472996 0.05340582578127627"/>
    <axis xyz="1 0 0"/>
    <parent link="front_right_wheel_link"/>
    <child link="front_right_roller5_link"/>
    <dynamics damping="0.001" friction="0.0001"/>
  </joint>
  <link name="front_right_roller4_link">
    <visual>
      <origin rpy="0 0 0" xyz="0 0 0"/>
      <geometry>
        <mesh filename="../meshes/mecanum_roller.dae" scale="0.6 0.6 0.6"/>
      </geometry>
    </visual>
    <collision>
      <geometry>
        <mesh filename="../meshes/mecanum_roller.stl" scale="0.6 0.6 0.6"/>
      </geometry>
    </collision>
    <inertial>
      <origin xyz="0 0 0"/>
      <mass value="0.3"/>
      <inertia ixx="0.00024000" ixy="0.0" ixz="0.0" iyy="0.00076000" iyz="0.0" izz="0.00076000"/>
    </inertial>
  </link>
  <joint name="front_right_roller4_joint" type="continuous">
    <origin rpy="-1.3449626171032882 0.2202852738547472 0.7603177925108144" xyz="0 0.016594212597934678 0.051071734925049746"/>
    <axis xyz="1 0 0"/>
    <parent link="front_right_wheel_link"/>
    <child link="front_right_roller4_link"/>
    <dynamics damping="0.001" friction="0.0001"/>
  </joint>
  <link name="front_right_roller3_link">
    <visual>
      <origin rpy="0 0 0" xyz="0 0 0"/>
      <geometry>
        <mesh filename="../meshes/mecanum_roller.dae" scale="0.6 0.6 0.6"/>
      </geometry>
    </visual>
    <collision>
      <geometry>
        <mesh filename="../meshes/mecanum_roller.stl" scale="0.6 0.6 0.6"/>
      </geometry>
    </collision>
    <inertial>
      <origin xyz="0 0 0"/>
      <mass value="0.3"/>
      <inertia ixx="0.00024000" ixy="0.0" ixz="0.0" iyy="0.00076000" iyz="0.0" izz="0.00076000"/>
    </inertial>
  </link>
  <joint name="front_right_roller3_joint" type="continuous">
    <origin rpy="-1.0038406803226867 0.4928592704898485 0.6390993414905141" xyz="0 0.03593231356147068 0.03990687712813607"/>
    <axis xyz="1 0 0"/>
    <parent link="front_right_wheel_link"/>
    <child link="front_right_roller3_link"/>
    <dynamics damping="0.001" friction="0.0001"/>
  </joint>
  <link name="front_right_roller2_link">
    <visual>
      <origin rpy="0 0 0" xyz="0 0 0"/>
      <geometry>
        <mesh filename="../meshes/mecanum_roller.dae" scale="0.6 0.6 0.6"/>
      </geometry>
    </visual>
    <collision>
      <geometry>
        <mesh filename="../meshes/mecanum_roller.stl" scale="0.6 0.6 0.6"/>
      </geometry>
    </collision>
    <inertial>
      <origin xyz="0 0 0"/>
      <mass value="0.3"/>
      <inertia ixx="0.00024000" ixy="0.0" ixz="0.0" iyy="0.00076000" iyz="0.0" izz="0.00076000"/>
    </inertial>
  </link>
  <joint name="front_right_roller2_joint" type="continuous">
    <origin rpy="-0.5619350361043128 0.702298780729168 0.3863003038769115" xyz="0 0.049057391075407665 0.02184175773317047"/>
    <axis xyz="1 0 0"/>
    <parent link="front_right_wheel_link"/>
    <child link="front_right_roller2_link"/>
    <dynamics damping="0.001" friction="0.0001"/>
  </joint>
  <link name="front_right_roller1_link">
    <visual>
      <origin rpy="0 0 0" xyz="0 0 0"/>
      <geometry>
        <mesh filename="../meshes/mecanum_roller.dae" scale="0.6 0.6 0.6"/>
      </geometry>
    </visual>
    <collision>
      <geometry>
        <mesh filename="../meshes/mecanum_roller.stl" scale="0.6 0.6 0.6"/>
      </geometry>
    </collision>
    <inertial>
      <origin xyz="0 0 0"/>
      <mass value="0.3"/>
      <inertia ixx="0.00024000" ixy="0.0" ixz="0.0" iyy="0.00076000" iyz="0.0" izz="0.00076000"/>
    </inertial>
  </link>
  <joint name="front_right_roller1_joint" type="continuous">
    <origin rpy="-0.0 0.7853981633974482 0.0" xyz="0 0.0537 0.0"/>
    <axis xyz="1 0 0"/>
    <parent link="front_right_wheel_link"/>
    <child link="front_right_roller1_link"/>
    <dynamics damping="0.001" friction="0.0001"/>
  </joint>
  
<link name="rear_right_wheel_link">
    <visual>
      <origin rpy="0 0 0" xyz="0 0 0"/>
      <geometry>
        <mesh filename="../meshes/mecanum_wheel.dae" scale="0.6 0.6 0.6"/>
      </geometry>
    </visual>
    <collision>
      <origin rpy="0 0 0" xyz="0 0 0"/>
      <geometry>
        <mesh filename="../meshes/mecanum_wheel.stl" scale="0.6 0.6 0.6"/>
      </geometry>
    </collision>
    <inertial>
      <origin xyz="0 0 0" />
      <mass value="2.0"/>
      <inertia ixx="0.042025" ixy="0.0" ixz="0.0" iyy="0.024279" iyz="0.0" izz="0.024279"/>
    </inertial>
  </link>
  <link name="rear_right_roller15_link">
    <visual>
      <origin rpy="0 0 0" xyz="0 0 0"/>
      <geometry>
        <mesh filename="../meshes/mecanum_roller.dae" scale="0.6 0.6 0.6"/>
      </geometry>
    </visual>
    <collision>
      <geometry>
        <mesh filename="../meshes/mecanum_roller.stl" scale="0.6 0.6 0.6"/>
      </geometry>
    </collision>
    <inertial>
      <origin xyz="0 0 0"/>
      <mass value="0.3"/>
      <inertia ixx="0.00024000" ixy="0.0" ixz="0.0" iyy="0.00076000" iyz="0.0" izz="0.00076000"/>
    </inertial>
  </link>
  <joint name="rear_right_roller15_joint" type="continuous">
    <origin rpy="0.5619350361043127 -0.7022987807291682 0.38630030387691144" xyz="0 0.04905739107540767 -0.021841757733170465"/>
    <axis xyz="1 0 0"/>
    <parent link="rear_right_wheel_link"/>
    <child link="rear_right_roller15_link"/>
    <dynamics damping="0.001" friction="0.0001"/>
  </joint>
  <link name="rear_right_roller14_link">
    <visual>
      <origin rpy="0 0 0" xyz="0 0 0"/>
      <geometry>
        <mesh filename="../meshes/mecanum_roller.dae" scale="0.6 0.6 0.6"/>
      </geometry>
    </visual>
    <collision>
      <geometry>
        <mesh filename="../meshes/mecanum_roller.stl" scale="0.6 0.6 0.6"/>
      </geometry>
    </collision>
    <inertial>
      <origin xyz="0 0 0"/>
      <mass value="0.3"/>
      <inertia ixx="0.00024000" ixy="0.0" ixz="0.0" iyy="0.00076000" iyz="0.0" izz="0.00076000"/>
    </inertial>
  </link>
  <joint name="rear_right_roller14_joint" type="continuous">
    <origin rpy="1.0038406803226874 -0.4928592704898482 0.6390993414905143" xyz="0 0.03593231356147066 -0.039906877128136085"/>
    <axis xyz="1 0 0"/>
    <parent link="rear_right_wheel_link"/>
    <child link="rear_right_roller14_link"/>
    <dynamics damping="0.001" friction="0.0001"/>
  </joint>
  <link name="rear_right_roller13_link">
    <visual>
      <origin rpy="0 0 0" xyz="0 0 0"/>
      <geometry>
        <mesh filename="../meshes/mecanum_roller.dae" scale="0.6 0.6 0.6"/>
      </geometry>
    </visual>
    <collision>
      <geometry>
        <mesh filename="../meshes/mecanum_roller.stl" scale="0.6 0.6 0.6"/>
      </geometry>
    </collision>
    <inertial>
      <origin xyz="0 0 0"/>
      <mass value="0.3"/>
      <inertia ixx="0.00024000" ixy="0.0" ixz="0.0" iyy="0.00076000" iyz="0.0" izz="0.00076000"/>
    </inertial>
  </link>
  <joint name="rear_right_roller13_joint" type="continuous">
    <origin rpy="1.3449626171032882 -0.22028527385474703 0.7603177925108144" xyz="0 0.01659421259793466 -0.051071734925049746"/>
    <axis xyz="1 0 0"/>
    <parent link="rear_right_wheel_link"/>
    <child link="rear_right_roller13_link"/>
    <dynamics damping="0.001" friction="0.0001"/>
  </joint>
  <link name="rear_right_roller12_link">
    <visual>
      <origin rpy="0 0 0" xyz="0 0 0"/>
      <geometry>
        <mesh filename="../meshes/mecanum_roller.dae" scale="0.6 0.6 0.6"/>
      </geometry>
    </visual>
    <collision>
      <geometry>
        <mesh filename="../meshes/mecanum_roller.stl" scale="0.6 0.6 0.6"/>
      </geometry>
    </collision>
    <inertial>
      <origin xyz="0 0 0"/>
      <mass value="0.3"/>
      <inertia ixx="0.00024000" ixy="0.0" ixz="0.0" iyy="0.00076000" iyz="0.0" izz="0.00076000"/>
    </inertial>
  </link>
  <joint name="rear_right_roller12_joint" type="continuous">
    <origin rpy="-1.4966127917301506 0.07398025001120935 0.7826515949744619" xyz="0 -0.0056131784774729855 -0.05340582578127628"/>
    <axis xyz="1 0 0"/>
    <parent link="rear_right_wheel_link"/>
    <child link="rear_right_roller12_link"/>
    <dynamics damping="0.001" friction="0.0001"/>
  </joint>
  <link name="rear_right_roller11_link">
    <visual>
      <origin rpy="0 0 0" xyz="0 0 0"/>
      <geometry>
        <mesh filename="../meshes/mecanum_roller.dae" scale="0.6 0.6 0.6"/>
      </geometry>
    </visual>
    <collision>
      <geometry>
        <mesh filename="../meshes/mecanum_roller.stl" scale="0.6 0.6 0.6"/>
      </geometry>
    </collision>
    <inertial>
      <origin xyz="0 0 0"/>
      <mass value="0.3"/>
      <inertia ixx="0.00024000" ixy="0.0" ixz="0.0" iyy="0.00076000" iyz="0.0" izz="0.00076000"/>
    </inertial>
  </link>
  <joint name="rear_right_roller11_joint" type="continuous">
    <origin rpy="-1.1831996401397156 0.3613671239067081 0.7137243789447655" xyz="0 -0.026850000000000023 -0.04650556418322434"/>
    <axis xyz="1 0 0"/>
    <parent link="rear_right_wheel_link"/>
    <child link="rear_right_roller11_link"/>
    <dynamics damping="0.001" friction="0.0001"/>
  </joint>
  <link name="rear_right_roller10_link">
    <visual>
      <origin rpy="0 0 0" xyz="0 0 0"/>
      <geometry>
        <mesh filename="../meshes/mecanum_roller.dae" scale="0.6 0.6 0.6"/>
      </geometry>
    </visual>
    <collision>
      <geometry>
        <mesh filename="../meshes/mecanum_roller.stl" scale="0.6 0.6 0.6"/>
      </geometry>
    </collision>
    <inertial>
      <origin xyz="0 0 0"/>
      <mass value="0.3"/>
      <inertia ixx="0.00024000" ixy="0.0" ixz="0.0" iyy="0.00076000" iyz="0.0" izz="0.00076000"/>
    </inertial>
  </link>
  <joint name="rear_right_roller10_joint" type="continuous">
    <origin rpy="-0.7989541677433551 0.6090169187607924 0.5313896516603533" xyz="0 -0.04344421259793468 -0.0315640680481058"/>
    <axis xyz="1 0 0"/>
    <parent link="rear_right_wheel_link"/>
    <child link="rear_right_roller10_link"/>
    <dynamics damping="0.001" friction="0.0001"/>
  </joint>
  <link name="rear_right_roller9_link">
    <visual>
      <origin rpy="0 0 0" xyz="0 0 0"/>
      <geometry>
        <mesh filename="../meshes/mecanum_roller.dae" scale="0.6 0.6 0.6"/>
      </geometry>
    </visual>
    <collision>
      <geometry>
        <mesh filename="../meshes/mecanum_roller.stl" scale="0.6 0.6 0.6"/>
      </geometry>
    </collision>
    <inertial>
      <origin xyz="0 0 0"/>
      <mass value="0.3"/>
      <inertia ixx="0.00024000" ixy="0.0" ixz="0.0" iyy="0.00076000" iyz="0.0" izz="0.00076000"/>
    </inertial>
  </link>
  <joint name="rear_right_roller9_joint" type="continuous">
    <origin rpy="-0.29200750368454736 0.7637777909460687 0.20499125187874406" xyz="0 -0.052526526159405354 -0.011164857796913686"/>
    <axis xyz="1 0 0"/>
    <parent link="rear_right_wheel_link"/>
    <child link="rear_right_roller9_link"/>
    <dynamics damping="0.001" friction="0.0001"/>
  </joint>
  <link name="rear_right_roller8_link">
    <visual>
      <origin rpy="0 0 0" xyz="0 0 0"/>
      <geometry>
        <mesh filename="../meshes/mecanum_roller.dae" scale="0.6 0.6 0.6"/>
      </geometry>
    </visual>
    <collision>
      <geometry>
        <mesh filename="../meshes/mecanum_roller.stl" scale="0.6 0.6 0.6"/>
      </geometry>
    </collision>
    <inertial>
      <origin xyz="0 0 0"/>
      <mass value="0.3"/>
      <inertia ixx="0.00024000" ixy="0.0" ixz="0.0" iyy="0.00076000" iyz="0.0" izz="0.00076000"/>
    </inertial>
  </link>
  <joint name="rear_right_roller8_joint" type="continuous">
    <origin rpy="0.2920075036845471 0.7637777909460687 -0.20499125187874387" xyz="0 -0.05252652615940536 0.011164857796913676"/>
    <axis xyz="1 0 0"/>
    <parent link="rear_right_wheel_link"/>
    <child link="rear_right_roller8_link"/>
    <dynamics damping="0.001" friction="0.0001"/>
  </joint>
  <link name="rear_right_roller7_link">
    <visual>
      <origin rpy="0 0 0" xyz="0 0 0"/>
      <geometry>
        <mesh filename="../meshes/mecanum_roller.dae" scale="0.6 0.6 0.6"/>
      </geometry>
    </visual>
    <collision>
      <geometry>
        <mesh filename="../meshes/mecanum_roller.stl" scale="0.6 0.6 0.6"/>
      </geometry>
    </collision>
    <inertial>
      <origin xyz="0 0 0"/>
      <mass value="0.3"/>
      <inertia ixx="0.00024000" ixy="0.0" ixz="0.0" iyy="0.00076000" iyz="0.0" izz="0.00076000"/>
    </inertial>
  </link>
  <joint name="rear_right_roller7_joint" type="continuous">
    <origin rpy="0.7989541677433554 0.6090169187607923 -0.5313896516603536" xyz="0 -0.04344421259793467 0.03156406804810581"/>
    <axis xyz="1 0 0"/>
    <parent link="rear_right_wheel_link"/>
    <child link="rear_right_roller7_link"/>
    <dynamics damping="0.001" friction="0.0001"/>
  </joint>
  <link name="rear_right_roller6_link">
    <visual>
      <origin rpy="0 0 0" xyz="0 0 0"/>
      <geometry>
        <mesh filename="../meshes/mecanum_roller.dae" scale="0.6 0.6 0.6"/>
      </geometry>
    </visual>
    <collision>
      <geometry>
        <mesh filename="../meshes/mecanum_roller.stl" scale="0.6 0.6 0.6"/>
      </geometry>
    </collision>
    <inertial>
      <origin xyz="0 0 0"/>
      <mass value="0.3"/>
      <inertia ixx="0.00024000" ixy="0.0" ixz="0.0" iyy="0.00076000" iyz="0.0" izz="0.00076000"/>
    </inertial>
  </link>
  <joint name="rear_right_roller6_joint" type="continuous">
    <origin rpy="1.1831996401397162 0.3613671239067076 -0.7137243789447657" xyz="0 -0.026849999999999985 0.04650556418322435"/>
    <axis xyz="1 0 0"/>
    <parent link="rear_right_wheel_link"/>
    <child link="rear_right_roller6_link"/>
    <dynamics damping="0.001" friction="0.0001"/>
  </joint>
  <link name="rear_right_roller5_link">
    <visual>
      <origin rpy="0 0 0" xyz="0 0 0"/>
      <geometry>
        <mesh filename="../meshes/mecanum_roller.dae" scale="0.6 0.6 0.6"/>
      </geometry>
    </visual>
    <collision>
      <geometry>
        <mesh filename="../meshes/mecanum_roller.stl" scale="0.6 0.6 0.6"/>
      </geometry>
    </collision>
    <inertial>
      <origin xyz="0 0 0"/>
      <mass value="0.3"/>
      <inertia ixx="0.00024000" ixy="0.0" ixz="0.0" iyy="0.00076000" iyz="0.0" izz="0.00076000"/>
    </inertial>
  </link>
  <joint name="rear_right_roller5_joint" type="continuous">
    <origin rpy="1.4966127917301504 0.07398025001120949 -0.7826515949744619" xyz="0 -0.005613178477472996 0.05340582578127627"/>
    <axis xyz="1 0 0"/>
    <parent link="rear_right_wheel_link"/>
    <child link="rear_right_roller5_link"/>
    <dynamics damping="0.001" friction="0.0001"/>
  </joint>
  <link name="rear_right_roller4_link">
    <visual>
      <origin rpy="0 0 0" xyz="0 0 0"/>
      <geometry>
        <mesh filename="../meshes/mecanum_roller.dae" scale="0.6 0.6 0.6"/>
      </geometry>
    </visual>
    <collision>
      <geometry>
        <mesh filename="../meshes/mecanum_roller.stl" scale="0.6 0.6 0.6"/>
      </geometry>
    </collision>
    <inertial>
      <origin xyz="0 0 0"/>
      <mass value="0.3"/>
      <inertia ixx="0.00024000" ixy="0.0" ixz="0.0" iyy="0.00076000" iyz="0.0" izz="0.00076000"/>
    </inertial>
  </link>
  <joint name="rear_right_roller4_joint" type="continuous">
    <origin rpy="-1.3449626171032882 -0.2202852738547472 -0.7603177925108144" xyz="0 0.016594212597934678 0.051071734925049746"/>
    <axis xyz="1 0 0"/>
    <parent link="rear_right_wheel_link"/>
    <child link="rear_right_roller4_link"/>
    <dynamics damping="0.001" friction="0.0001"/>
  </joint>
  <link name="rear_right_roller3_link">
    <visual>
      <origin rpy="0 0 0" xyz="0 0 0"/>
      <geometry>
        <mesh filename="../meshes/mecanum_roller.dae" scale="0.6 0.6 0.6"/>
      </geometry>
    </visual>
    <collision>
      <geometry>
        <mesh filename="../meshes/mecanum_roller.stl" scale="0.6 0.6 0.6"/>
      </geometry>
    </collision>
    <inertial>
      <origin xyz="0 0 0"/>
      <mass value="0.3"/>
      <inertia ixx="0.00024000" ixy="0.0" ixz="0.0" iyy="0.00076000" iyz="0.0" izz="0.00076000"/>
    </inertial>
  </link>
  <joint name="rear_right_roller3_joint" type="continuous">
    <origin rpy="-1.0038406803226867 -0.4928592704898485 -0.6390993414905141" xyz="0 0.03593231356147068 0.03990687712813607"/>
    <axis xyz="1 0 0"/>
    <parent link="rear_right_wheel_link"/>
    <child link="rear_right_roller3_link"/>
    <dynamics damping="0.001" friction="0.0001"/>
  </joint>
  <link name="rear_right_roller2_link">
    <visual>
      <origin rpy="0 0 0" xyz="0 0 0"/>
      <geometry>
        <mesh filename="../meshes/mecanum_roller.dae" scale="0.6 0.6 0.6"/>
      </geometry>
    </visual>
    <collision>
      <geometry>
        <mesh filename="../meshes/mecanum_roller.stl" scale="0.6 0.6 0.6"/>
      </geometry>
    </collision>
    <inertial>
      <origin xyz="0 0 0"/>
      <mass value="0.3"/>
      <inertia ixx="0.00024000" ixy="0.0" ixz="0.0" iyy="0.00076000" iyz="0.0" izz="0.00076000"/>
    </inertial>
  </link>
  <joint name="rear_right_roller2_joint" type="continuous">
    <origin rpy="-0.5619350361043128 -0.702298780729168 -0.3863003038769115" xyz="0 0.049057391075407665 0.02184175773317047"/>
    <axis xyz="1 0 0"/>
    <parent link="rear_right_wheel_link"/>
    <child link="rear_right_roller2_link"/>
    <dynamics damping="0.001" friction="0.0001"/>
  </joint>
  <link name="rear_right_roller1_link">
    <visual>
      <origin rpy="0 0 0" xyz="0 0 0"/>
      <geometry>
        <mesh filename="../meshes/mecanum_roller.dae" scale="0.6 0.6 0.6"/>
      </geometry>
    </visual>
    <collision>
      <geometry>
        <mesh filename="../meshes/mecanum_roller.stl" scale="0.6 0.6 0.6"/>
      </geometry>
    </collision>
    <inertial>
      <origin xyz="0 0 0"/>
      <mass value="0.3"/>
      <inertia ixx="0.00024000" ixy="0.0" ixz="0.0" iyy="0.00076000" iyz="0.0" izz="0.00076000"/>
    </inertial>
  </link>
  <joint name="rear_right_roller1_joint" type="continuous">
    <origin rpy="-0.0 -0.7853981633974482 -0.0" xyz="0 0.0537 0.0"/>
    <axis xyz="1 0 0"/>
    <parent link="rear_right_wheel_link"/>
    <child link="rear_right_roller1_link"/>
    <dynamics damping="0.001" friction="0.0001"/>
  </joint>

<link name="rear_left_wheel_link">
    <visual>
      <origin rpy="0 0 0" xyz="0 0 0"/>
      <geometry>
        <mesh filename="../meshes/mecanum_wheel.dae" scale="0.6 0.6 0.6"/>
      </geometry>
    </visual>
    <collision>
      <origin rpy="0 0 0" xyz="0 0 0"/>
      <geometry>
        <mesh filename="../meshes/mecanum_wheel.stl" scale="0.6 0.6 0.6"/>
      </geometry>
    </collision>
    <inertial>
      <origin xyz="0 0 0" />
      <mass value="2.0"/>
      <inertia ixx="0.042025" ixy="0.0" ixz="0.0" iyy="0.024279" iyz="0.0" izz="0.024279"/>
    </inertial>
  </link>
  <link name="rear_left_roller15_link">
    <visual>
      <origin rpy="0 0 0" xyz="0 0 0"/>
      <geometry>
        <mesh filename="../meshes/mecanum_roller.dae" scale="0.6 0.6 0.6"/>
      </geometry>
    </visual>
    <collision>
      <geometry>
        <mesh filename="../meshes/mecanum_roller.stl" scale="0.6 0.6 0.6"/>
      </geometry>
    </collision>
    <inertial>
      <origin xyz="0 0 0"/>
      <mass value="0.3"/>
      <inertia ixx="0.00024000" ixy="0.0" ixz="0.0" iyy="0.00076000" iyz="0.0" izz="0.00076000"/>
    </inertial>
  </link>
  <joint name="rear_left_roller15_joint" type="continuous">
    <origin rpy="0.5619350361043127 0.7022987807291682 -0.38630030387691144" xyz="0 0.04905739107540767 -0.021841757733170465"/>
    <axis xyz="1 0 0"/>
    <parent link="rear_left_wheel_link"/>
    <child link="rear_left_roller15_link"/>
    <dynamics damping="0.001" friction="0.0001"/>
  </joint>
  <link name="rear_left_roller14_link">
    <visual>
      <origin rpy="0 0 0" xyz="0 0 0"/>
      <geometry>
        <mesh filename="../meshes/mecanum_roller.dae" scale="0.6 0.6 0.6"/>
      </geometry>
    </visual>
    <collision>
      <geometry>
        <mesh filename="../meshes/mecanum_roller.stl" scale="0.6 0.6 0.6"/>
      </geometry>
    </collision>
    <inertial>
      <origin xyz="0 0 0"/>
      <mass value="0.3"/>
      <inertia ixx="0.00024000" ixy="0.0" ixz="0.0" iyy="0.00076000" iyz="0.0" izz="0.00076000"/>
    </inertial>
  </link>
  <joint name="rear_left_roller14_joint" type="continuous">
    <origin rpy="1.0038406803226874 0.4928592704898482 -0.6390993414905143" xyz="0 0.03593231356147066 -0.039906877128136085"/>
    <axis xyz="1 0 0"/>
    <parent link="rear_left_wheel_link"/>
    <child link="rear_left_roller14_link"/>
    <dynamics damping="0.001" friction="0.0001"/>
  </joint>
  <link name="rear_left_roller13_link">
    <visual>
      <origin rpy="0 0 0" xyz="0 0 0"/>
      <geometry>
        <mesh filename="../meshes/mecanum_roller.dae" scale="0.6 0.6 0.6"/>
      </geometry>
    </visual>
    <collision>
      <geometry>
        <mesh filename="../meshes/mecanum_roller.stl" scale="0.6 0.6 0.6"/>
      </geometry>
    </collision>
    <inertial>
      <origin xyz="0 0 0"/>
      <mass value="0.3"/>
      <inertia ixx="0.00024000" ixy="0.0" ixz="0.0" iyy="0.00076000" iyz="0.0" izz="0.00076000"/>
    </inertial>
  </link>
  <joint name="rear_left_roller13_joint" type="continuous">
    <origin rpy="1.3449626171032882 0.22028527385474703 -0.7603177925108144" xyz="0 0.01659421259793466 -0.051071734925049746"/>
    <axis xyz="1 0 0"/>
    <parent link="rear_left_wheel_link"/>
    <child link="rear_left_roller13_link"/>
    <dynamics damping="0.001" friction="0.0001"/>
  </joint>
  <link name="rear_left_roller12_link">
    <visual>
      <origin rpy="0 0 0" xyz="0 0 0"/>
      <geometry>
        <mesh filename="../meshes/mecanum_roller.dae" scale="0.6 0.6 0.6"/>
      </geometry>
    </visual>
    <collision>
      <geometry>
        <mesh filename="../meshes/mecanum_roller.stl" scale="0.6 0.6 0.6"/>
      </geometry>
    </collision>
    <inertial>
      <origin xyz="0 0 0"/>
      <mass value="0.3"/>
      <inertia ixx="0.00024000" ixy="0.0" ixz="0.0" iyy="0.00076000" iyz="0.0" izz="0.00076000"/>
    </inertial>
  </link>
  <joint name="rear_left_roller12_joint" type="continuous">
    <origin rpy="-1.4966127917301506 -0.07398025001120935 -0.7826515949744619" xyz="0 -0.0056131784774729855 -0.05340582578127628"/>
    <axis xyz="1 0 0"/>
    <parent link="rear_left_wheel_link"/>
    <child link="rear_left_roller12_link"/>
    <dynamics damping="0.001" friction="0.0001"/>
  </joint>
  <link name="rear_left_roller11_link">
    <visual>
      <origin rpy="0 0 0" xyz="0 0 0"/>
      <geometry>
        <mesh filename="../meshes/mecanum_roller.dae" scale="0.6 0.6 0.6"/>
      </geometry>
    </visual>
    <collision>
      <geometry>
        <mesh filename="../meshes/mecanum_roller.stl" scale="0.6 0.6 0.6"/>
      </geometry>
    </collision>
    <inertial>
      <origin xyz="0 0 0"/>
      <mass value="0.3"/>
      <inertia ixx="0.00024000" ixy="0.0" ixz="0.0" iyy="0.00076000" iyz="0.0" izz="0.00076000"/>
    </inertial>
  </link>
  <joint name="rear_left_roller11_joint" type="continuous">
    <origin rpy="-1.1831996401397156 -0.3613671239067081 -0.7137243789447655" xyz="0 -0.026850000000000023 -0.04650556418322434"/>
    <axis xyz="1 0 0"/>
    <parent link="rear_left_wheel_link"/>
    <child link="rear_left_roller11_link"/>
    <dynamics damping="0.001" friction="0.0001"/>
  </joint>
  <link name="rear_left_roller10_link">
    <visual>
      <origin rpy="0 0 0" xyz="0 0 0"/>
      <geometry>
        <mesh filename="../meshes/mecanum_roller.dae" scale="0.6 0.6 0.6"/>
      </geometry>
    </visual>
    <collision>
      <geometry>
        <mesh filename="../meshes/mecanum_roller.stl" scale="0.6 0.6 0.6"/>
      </geometry>
    </collision>
    <inertial>
      <origin xyz="0 0 0"/>
      <mass value="0.3"/>
      <inertia ixx="0.00024000" ixy="0.0" ixz="0.0" iyy="0.00076000" iyz="0.0" izz="0.00076000"/>
    </inertial>
  </link>
  <joint name="rear_left_roller10_joint" type="continuous">
    <origin rpy="-0.7989541677433551 -0.6090169187607924 -0.5313896516603533" xyz="0 -0.04344421259793468 -0.0315640680481058"/>
    <axis xyz="1 0 0"/>
    <parent link="rear_left_wheel_link"/>
    <child link="rear_left_roller10_link"/>
    <dynamics damping="0.001" friction="0.0001"/>
  </joint>
  <link name="rear_left_roller9_link">
    <visual>
      <origin rpy="0 0 0" xyz="0 0 0"/>
      <geometry>
        <mesh filename="../meshes/mecanum_roller.dae" scale="0.6 0.6 0.6"/>
      </geometry>
    </visual>
    <collision>
      <geometry>
        <mesh filename="../meshes/mecanum_roller.stl" scale="0.6 0.6 0.6"/>
      </geometry>
    </collision>
    <inertial>
      <origin xyz="0 0 0"/>
      <mass value="0.3"/>
      <inertia ixx="0.00024000" ixy="0.0" ixz="0.0" iyy="0.00076000" iyz="0.0" izz="0.00076000"/>
    </inertial>
  </link>
  <joint name="rear_left_roller9_joint" type="continuous">
    <origin rpy="-0.29200750368454736 -0.7637777909460687 -0.20499125187874406" xyz="0 -0.052526526159405354 -0.011164857796913686"/>
    <axis xyz="1 0 0"/>
    <parent link="rear_left_wheel_link"/>
    <child link="rear_left_roller9_link"/>
    <dynamics damping="0.001" friction="0.0001"/>
  </joint>
  <link name="rear_left_roller8_link">
    <visual>
      <origin rpy="0 0 0" xyz="0 0 0"/>
      <geometry>
        <mesh filename="../meshes/mecanum_roller.dae" scale="0.6 0.6 0.6"/>
      </geometry>
    </visual>
    <collision>
      <geometry>
        <mesh filename="../meshes/mecanum_roller.stl" scale="0.6 0.6 0.6"/>
      </geometry>
    </collision>
    <inertial>
      <origin xyz="0 0 0"/>
      <mass value="0.3"/>
      <inertia ixx="0.00024000" ixy="0.0" ixz="0.0" iyy="0.00076000" iyz="0.0" izz="0.00076000"/>
    </inertial>
  </link>
  <joint name="rear_left_roller8_joint" type="continuous">
    <origin rpy="0.2920075036845471 -0.7637777909460687 0.20499125187874387" xyz="0 -0.05252652615940536 0.011164857796913676"/>
    <axis xyz="1 0 0"/>
    <parent link="rear_left_wheel_link"/>
    <child link="rear_left_roller8_link"/>
    <dynamics damping="0.001" friction="0.0001"/>
  </joint>
  <link name="rear_left_roller7_link">
    <visual>
      <origin rpy="0 0 0" xyz="0 0 0"/>
      <geometry>
        <mesh filename="../meshes/mecanum_roller.dae" scale="0.6 0.6 0.6"/>
      </geometry>
    </visual>
    <collision>
      <geometry>
        <mesh filename="../meshes/mecanum_roller.stl" scale="0.6 0.6 0.6"/>
      </geometry>
    </collision>
    <inertial>
      <origin xyz="0 0 0"/>
      <mass value="0.3"/>
      <inertia ixx="0.00024000" ixy="0.0" ixz="0.0" iyy="0.00076000" iyz="0.0" izz="0.00076000"/>
    </inertial>
  </link>
  <joint name="rear_left_roller7_joint" type="continuous">
    <origin rpy="0.7989541677433554 -0.6090169187607923 0.5313896516603536" xyz="0 -0.04344421259793467 0.03156406804810581"/>
    <axis xyz="1 0 0"/>
    <parent link="rear_left_wheel_link"/>
    <child link="rear_left_roller7_link"/>
    <dynamics damping="0.001" friction="0.0001"/>
  </joint>
  <link name="rear_left_roller6_link">
    <visual>
      <origin rpy="0 0 0" xyz="0 0 0"/>
      <geometry>
        <mesh filename="../meshes/mecanum_roller.dae" scale="0.6 0.6 0.6"/>
      </geometry>
    </visual>
    <collision>
      <geometry>
        <mesh filename="../meshes/mecanum_roller.stl" scale="0.6 0.6 0.6"/>
      </geometry>
    </collision>
    <inertial>
      <origin xyz="0 0 0"/>
      <mass value="0.3"/>
      <inertia ixx="0.00024000" ixy="0.0" ixz="0.0" iyy="0.00076000" iyz="0.0" izz="0.00076000"/>
    </inertial>
  </link>
  <joint name="rear_left_roller6_joint" type="continuous">
    <origin rpy="1.1831996401397162 -0.3613671239067076 0.7137243789447657" xyz="0 -0.026849999999999985 0.04650556418322435"/>
    <axis xyz="1 0 0"/>
    <parent link="rear_left_wheel_link"/>
    <child link="rear_left_roller6_link"/>
    <dynamics damping="0.001" friction="0.0001"/>
  </joint>
  <link name="rear_left_roller5_link">
    <visual>
      <origin rpy="0 0 0" xyz="0 0 0"/>
      <geometry>
        <mesh filename="../meshes/mecanum_roller.dae" scale="0.6 0.6 0.6"/>
      </geometry>
    </visual>
    <collision>
      <geometry>
        <mesh filename="../meshes/mecanum_roller.stl" scale="0.6 0.6 0.6"/>
      </geometry>
    </collision>
    <inertial>
      <origin xyz="0 0 0"/>
      <mass value="0.3"/>
      <inertia ixx="0.00024000" ixy="0.0" ixz="0.0" iyy="0.00076000" iyz="0.0" izz="0.00076000"/>
    </inertial>
  </link>
  <joint name="rear_left_roller5_joint" type="continuous">
    <origin rpy="1.4966127917301504 -0.07398025001120949 0.7826515949744619" xyz="0 -0.005613178477472996 0.05340582578127627"/>
    <axis xyz="1 0 0"/>
    <parent link="rear_left_wheel_link"/>
    <child link="rear_left_roller5_link"/>
    <dynamics damping="0.001" friction="0.0001"/>
  </joint>
  <link name="rear_left_roller4_link">
    <visual>
      <origin rpy="0 0 0" xyz="0 0 0"/>
      <geometry>
        <mesh filename="../meshes/mecanum_roller.dae" scale="0.6 0.6 0.6"/>
      </geometry>
    </visual>
    <collision>
      <geometry>
        <mesh filename="../meshes/mecanum_roller.stl" scale="0.6 0.6 0.6"/>
      </geometry>
    </collision>
    <inertial>
      <origin xyz="0 0 0"/>
      <mass value="0.3"/>
      <inertia ixx="0.00024000" ixy="0.0" ixz="0.0" iyy="0.00076000" iyz="0.0" izz="0.00076000"/>
    </inertial>
  </link>
  <joint name="rear_left_roller4_joint" type="continuous">
    <origin rpy="-1.3449626171032882 0.2202852738547472 0.7603177925108144" xyz="0 0.016594212597934678 0.051071734925049746"/>
    <axis xyz="1 0 0"/>
    <parent link="rear_left_wheel_link"/>
    <child link="rear_left_roller4_link"/>
    <dynamics damping="0.001" friction="0.0001"/>
  </joint>
  <link name="rear_left_roller3_link">
    <visual>
      <origin rpy="0 0 0" xyz="0 0 0"/>
      <geometry>
        <mesh filename="../meshes/mecanum_roller.dae" scale="0.6 0.6 0.6"/>
      </geometry>
    </visual>
    <collision>
      <geometry>
        <mesh filename="../meshes/mecanum_roller.stl" scale="0.6 0.6 0.6"/>
      </geometry>
    </collision>
    <inertial>
      <origin xyz="0 0 0"/>
      <mass value="0.3"/>
      <inertia ixx="0.00024000" ixy="0.0" ixz="0.0" iyy="0.00076000" iyz="0.0" izz="0.00076000"/>
    </inertial>
  </link>
  <joint name="rear_left_roller3_joint" type="continuous">
    <origin rpy="-1.0038406803226867 0.4928592704898485 0.6390993414905141" xyz="0 0.03593231356147068 0.03990687712813607"/>
    <axis xyz="1 0 0"/>
    <parent link="rear_left_wheel_link"/>
    <child link="rear_left_roller3_link"/>
    <dynamics damping="0.001" friction="0.0001"/>
  </joint>
  <link name="rear_left_roller2_link">
    <visual>
      <origin rpy="0 0 0" xyz="0 0 0"/>
      <geometry>
        <mesh filename="../meshes/mecanum_roller.dae" scale="0.6 0.6 0.6"/>
      </geometry>
    </visual>
    <collision>
      <geometry>
        <mesh filename="../meshes/mecanum_roller.stl" scale="0.6 0.6 0.6"/>
      </geometry>
    </collision>
    <inertial>
      <origin xyz="0 0 0"/>
      <mass value="0.3"/>
      <inertia ixx="0.00024000" ixy="0.0" ixz="0.0" iyy="0.00076000" iyz="0.0" izz="0.00076000"/>
    </inertial>
  </link>
  <joint name="rear_left_roller2_joint" type="continuous">
    <origin rpy="-0.5619350361043128 0.702298780729168 0.3863003038769115" xyz="0 0.049057391075407665 0.02184175773317047"/>
    <axis xyz="1 0 0"/>
    <parent link="rear_left_wheel_link"/>
    <child link="rear_left_roller2_link"/>
    <dynamics damping="0.001" friction="0.0001"/>
  </joint>
  <link name="rear_left_roller1_link">
    <visual>
      <origin rpy="0 0 0" xyz="0 0 0"/>
      <geometry>
        <mesh filename="../meshes/mecanum_roller.dae" scale="0.6 0.6 0.6"/>
      </geometry>
    </visual>
    <collision>
      <geometry>
        <mesh filename="../meshes/mecanum_roller.stl" scale="0.6 0.6 0.6"/>
      </geometry>
    </collision>
    <inertial>
      <origin xyz="0 0 0"/>
      <mass value="0.3"/>
      <inertia ixx="0.00024000" ixy="0.0" ixz="0.0" iyy="0.00076000" iyz="0.0" izz="0.00076000"/>
    </inertial>
  </link>
  <joint name="rear_left_roller1_joint" type="continuous">
    <origin rpy="-0.0 0.7853981633974482 0.0" xyz="0 0.0537 0.0"/>
    <axis xyz="1 0 0"/>
    <parent link="rear_left_wheel_link"/>
    <child link="rear_left_roller1_link"/>
    <dynamics damping="0.001" friction="0.0001"/>
  </joint>


</robot>

