<?xml version="1.0"?>
<robot name="RoboMaster">
    <link name="robot_base">
        <inertial>
            <origin xyz="-0.355513 0.124679 0.066029" rpy="-0.000000 -1.570796 0.000000" />
            <inertia ixx="0.017589308201487" ixy="-7.7439198790158e-07" ixz="-4.6110514572507e-05" iyy="0.0051199987327979" iyz="-3.7897668285013e-06" izz="0.01451068068707" />
            <mass value="1.9340000152588" />
        </inertial>
        <collision name="RoboMaster">
            <origin xyz="-0.350000 0.125000 0.067444" rpy="0.000000 -1.570796 0.000000" />
            <geometry>
                <mesh filename="./robomaster_ep_robot_base_coll_1.dae" />
            </geometry>
        </collision>
        <visual name="base_link_visual">
            <origin xyz="-0.350000 0.123093 0.071201" rpy="-0.023726 4.701310 -3.118698" />
            <geometry>
                <mesh filename="./robomaster_ep_base_link_visual_vis_1.dae" />
            </geometry>
            <material name="base_link_visual_material">
                <color rgba="0.227713 0.227713 0.227713 1.0" />
            </material>
        </visual>
        <visual name="base_link_visual">
            <origin xyz="-0.350000 0.123093 0.071201" rpy="-0.023726 4.701310 -3.118698" />
            <geometry>
                <mesh filename="./robomaster_ep_base_link_visual_vis_2.dae" />
            </geometry>
            <material name="base_link_visual_material">
                <color rgba="0.028175 0.028175 0.028175 1.0" />
            </material>
        </visual>
        <visual name="base_link_visual">
            <origin xyz="-0.350000 0.123093 0.071201" rpy="-0.023726 4.701310 -3.118698" />
            <geometry>
                <mesh filename="./robomaster_ep_base_link_visual_vis_3.dae" />
            </geometry>
            <material name="base_link_visual_material">
                <color rgba="0.028175 0.028175 0.028175 1.0" />
            </material>
        </visual>
        <visual name="base_link_visual">
            <origin xyz="-0.350000 0.123093 0.071201" rpy="-0.023726 4.701310 -3.118698" />
            <geometry>
                <mesh filename="./robomaster_ep_base_link_visual_vis_4.dae" />
            </geometry>
            <material name="base_link_visual_material">
                <color rgba="0.028175 0.028175 0.028175 1.0" />
            </material>
        </visual>
        <visual name="base_link_visual">
            <origin xyz="-0.350000 0.123093 0.071201" rpy="-0.023726 4.701310 -3.118698" />
            <geometry>
                <mesh filename="./robomaster_ep_base_link_visual_vis_5.dae" />
            </geometry>
            <material name="base_link_visual_material">
                <color rgba="0.169785 0.169785 0.169785 1.0" />
            </material>
        </visual>
        <visual name="base_link_visual">
            <origin xyz="-0.350000 0.123093 0.071201" rpy="-0.023726 4.701310 -3.118698" />
            <geometry>
                <mesh filename="./robomaster_ep_base_link_visual_vis_6.dae" />
            </geometry>
            <material name="base_link_visual_material">
                <color rgba="0.028175 0.028175 0.028175 1.0" />
            </material>
        </visual>
        <visual name="base_link_visual">
            <origin xyz="-0.350000 0.123093 0.071201" rpy="-0.023726 4.701310 -3.118698" />
            <geometry>
                <mesh filename="./robomaster_ep_base_link_visual_vis_7.dae" />
            </geometry>
            <material name="base_link_visual_material">
                <color rgba="0.098969 0.098969 0.098969 1.0" />
            </material>
        </visual>
        <visual name="base_link_visual">
            <origin xyz="-0.350000 0.123093 0.071201" rpy="-0.023726 4.701310 -3.118698" />
            <geometry>
                <mesh filename="./robomaster_ep_base_link_visual_vis_8.dae" />
            </geometry>
            <material name="base_link_visual_material">
                <color rgba="0.254832 0.254832 0.254832 1.0" />
            </material>
        </visual>
        <visual name="base_link_visual">
            <origin xyz="-0.350000 0.123093 0.071201" rpy="-0.023726 4.701310 -3.118698" />
            <geometry>
                <mesh filename="./robomaster_ep_base_link_visual_vis_9.dae" />
            </geometry>
            <material name="base_link_visual_material">
                <color rgba="0.000000 0.000000 0.000000 1.0" />
            </material>
        </visual>
        <visual name="base_link_visual">
            <origin xyz="-0.350000 0.123093 0.071201" rpy="-0.023726 4.701310 -3.118698" />
            <geometry>
                <mesh filename="./robomaster_ep_base_link_visual_vis_10.dae" />
            </geometry>
            <material name="base_link_visual_material">
                <color rgba="0.098969 0.098969 0.098969 1.0" />
            </material>
        </visual>
        <visual name="base_link_visual">
            <origin xyz="-0.350000 0.123093 0.071201" rpy="-0.023726 4.701310 -3.118698" />
            <geometry>
                <mesh filename="./robomaster_ep_base_link_visual_vis_11.dae" />
            </geometry>
            <material name="base_link_visual_material">
                <color rgba="0.169785 0.169785 0.169785 1.0" />
            </material>
        </visual>
        <visual name="base_link_visual">
            <origin xyz="-0.350000 0.123093 0.071201" rpy="-0.023726 4.701310 -3.118698" />
            <geometry>
                <mesh filename="./robomaster_ep_base_link_visual_vis_12.dae" />
            </geometry>
            <material name="base_link_visual_material">
                <color rgba="0.028175 0.028175 0.028175 1.0" />
            </material>
        </visual>
        <visual name="base_link_visual">
            <origin xyz="-0.350000 0.123093 0.071201" rpy="-0.023726 4.701310 -3.118698" />
            <geometry>
                <mesh filename="./robomaster_ep_base_link_visual_vis_13.dae" />
            </geometry>
            <material name="base_link_visual_material">
                <color rgba="0.098113 0.098113 0.098113 1.0" />
            </material>
        </visual>
        <visual name="front_hit_sensor_link_visual">
            <origin xyz="-0.195117 0.124491 0.077526" rpy="-1.570858 3.156556 0.000403" />
            <geometry>
                <mesh filename="./robomaster_ep_front_hit_sensor_link_visual_vis_1.dae" />
            </geometry>
            <material name="front_hit_sensor_link_visual_material">
                <color rgba="0.169785 0.169785 0.169785 1.0" />
            </material>
        </visual>
        <visual name="front_led_link_visual">
            <origin xyz="-0.183659 0.123334 0.077340" rpy="-1.570776 3.151230 3.140798" />
            <geometry>
                <mesh filename="./robomaster_ep_front_led_link_visual_vis_1.dae" />
            </geometry>
            <material name="front_led_link_visual_material">
                <color rgba="0.780000 0.777358 0.777358 1.0" />
            </material>
        </visual>
        <visual name="left_hit_sensor_link_visual">
            <origin xyz="-0.352040 0.210820 0.066425" rpy="1.555835 3.141586 1.571201" />
            <geometry>
                <mesh filename="./robomaster_ep_left_hit_sensor_link_visual_vis_1.dae" />
            </geometry>
            <material name="left_hit_sensor_link_visual_material">
                <color rgba="0.169785 0.169785 0.169785 1.0" />
            </material>
        </visual>
        <visual name="left_led_link_visual">
            <origin xyz="-0.353518 0.221630 0.066595" rpy="1.558170 3.174514 1.571616" />
            <geometry>
                <mesh filename="./robomaster_ep_left_led_link_visual_vis_1.dae" />
            </geometry>
            <material name="left_led_link_visual_material">
                <color rgba="0.780000 0.777358 0.777358 1.0" />
            </material>
        </visual>
        <visual name="rear_hit_sensor_link_visual">
            <origin xyz="-0.505119 0.122010 0.069243" rpy="1.570860 3.126629 -3.141188" />
            <geometry>
                <mesh filename="./robomaster_ep_rear_hit_sensor_link_visual_vis_1.dae" />
            </geometry>
            <material name="rear_hit_sensor_link_visual_material">
                <color rgba="0.169785 0.169785 0.169785 1.0" />
            </material>
        </visual>
        <visual name="rear_led_link_visual">
            <origin xyz="-0.515956 0.124106 0.069047" rpy="-1.570639 3.191801 -0.000609" />
            <geometry>
                <mesh filename="./robomaster_ep_rear_led_link_visual_vis_1.dae" />
            </geometry>
            <material name="rear_led_link_visual_material">
                <color rgba="0.780000 0.777358 0.777358 1.0" />
            </material>
        </visual>
        <visual name="right_hit_sensor_link_visual">
            <origin xyz="-0.351971 0.040685 0.066414" rpy="1.555835 3.141586 1.571201" />
            <geometry>
                <mesh filename="./robomaster_ep_right_hit_sensor_link_visual_vis_1.dae" />
            </geometry>
            <material name="right_hit_sensor_link_visual_material">
                <color rgba="0.169785 0.169785 0.169785 1.0" />
            </material>
        </visual>
        <visual name="right_led_link_visual">
            <origin xyz="-0.351984 0.027039 0.066579" rpy="-1.586849 3.142395 1.571214" />
            <geometry>
                <mesh filename="./robomaster_ep_right_led_link_visual_vis_1.dae" />
            </geometry>
            <material name="right_led_link_visual_material">
                <color rgba="0.780000 0.777358 0.777358 1.0" />
            </material>
        </visual>
        <visual name="GyroSensor">
            <origin xyz="-0.350000 0.125000 0.067444" rpy="-3.141593 3.141593 -3.141593" />
            <geometry>
                <mesh filename="./robomaster_ep_GyroSensor_vis_1.dae" />
            </geometry>
            <material name="GyroSensor_material">
                <color rgba="0.676471 0.323529 0.323529 1.0" />
            </material>
        </visual>
        <visual name="Accelerometer">
            <origin xyz="-0.350000 0.125000 0.067444" rpy="-3.141593 3.141593 -3.141593" />
            <geometry>
                <mesh filename="./robomaster_ep_Accelerometer_vis_1.dae" />
            </geometry>
            <material name="Accelerometer_material">
                <color rgba="0.323529 0.323529 0.676471 1.0" />
            </material>
        </visual>
    </link>
    <joint type="fixed" name="arm_base_attachment_joint">
        <axis xyz="0 0 1" />
        <parent link="robot_base" />
        <child link="arm_base_link_respondable" />
        <origin xyz="-0.348720 0.125830 0.127151" rpy="-0.004234 1.585757 -0.003830" />
    </joint>
    <link name="arm_base_link_respondable">
        <inertial>
            <origin xyz="0.000000 0.000000 -0.000000" rpy="1.570799 3.141592 -0.010468" />
            <inertia ixx="0.00072019468651553" ixy="-2.9647946187585e-11" ixz="-1.8631618966786e-05" iyy="0.0022999993508077" iyz="5.7190505382992e-10" izz="0.0024997998783834" />
            <mass value="0.30000001192093" />
        </inertial>
        <collision name="arm_base_link_respondable">
            <origin xyz="-0.010620 -0.000534 -0.002359" rpy="1.570799 3.141592 -0.010468" />
            <geometry>
                <mesh filename="./robomaster_ep_arm_base_link_respondable_coll_1.dae" />
            </geometry>
        </collision>
        <visual name="arm_base_link_visual">
            <origin xyz="-0.017503 0.000081 -0.001144" rpy="1.571034 3.145504 -0.000324" />
            <geometry>
                <mesh filename="./robomaster_ep_arm_base_link_visual_vis_1.dae" />
            </geometry>
            <material name="arm_base_link_visual_material">
                <color rgba="0.028175 0.028000 0.028175 1.0" />
            </material>
        </visual>
        <visual name="arm_base_link_visual">
            <origin xyz="-0.017503 0.000081 -0.001144" rpy="1.571034 3.145504 -0.000324" />
            <geometry>
                <mesh filename="./robomaster_ep_arm_base_link_visual_vis_2.dae" />
            </geometry>
            <material name="arm_base_link_visual_material">
                <color rgba="1.000000 1.000000 1.000000 1.0" />
            </material>
        </visual>
        <visual name="arm_base_link_visual">
            <origin xyz="-0.017503 0.000081 -0.001144" rpy="1.571034 3.145504 -0.000324" />
            <geometry>
                <mesh filename="./robomaster_ep_arm_base_link_visual_vis_3.dae" />
            </geometry>
            <material name="arm_base_link_visual_material">
                <color rgba="0.028175 0.028000 0.028175 1.0" />
            </material>
        </visual>
        <visual name="arm_base_link_visual">
            <origin xyz="-0.017503 0.000081 -0.001144" rpy="1.571034 3.145504 -0.000324" />
            <geometry>
                <mesh filename="./robomaster_ep_arm_base_link_visual_vis_4.dae" />
            </geometry>
            <material name="arm_base_link_visual_material">
                <color rgba="0.028175 0.028000 0.028175 1.0" />
            </material>
        </visual>
    </link>
    <joint type="revolute" name="servo_motor_1">
        <axis xyz="0 0 1" />
        <limit effort="1000.0" lower="-0.27401667833328" velocity="5.1312680244446" upper="1.3840461373329" />
        <parent link="arm_base_link_respondable" />
        <child link="arm_1_link_respondable" />
        <origin xyz="-0.030741 -0.025571 0.010396" rpy="-1.570797 -1.570796 0.000000" />
    </joint>
    <link name="arm_1_link_respondable">
        <inertial>
            <origin xyz="-0.000559 -0.001173 0.023592" rpy="1.570958 3.142942 0.060996" />
            <inertia ixx="0.015559326757555" ixy="0.00016358625834718" ixz="-0.00084468883193591" iyy="0.016156487726318" iyz="0.0022918940812945" izz="0.0018599644109959" />
            <mass value="0.056000001728535" />
        </inertial>
        <collision name="arm_1_link_respondable">
            <origin xyz="0.006169 -0.058604 0.023587" rpy="1.570958 3.142942 0.060996" />
            <geometry>
                <mesh filename="./robomaster_ep_arm_1_link_respondable_coll_1.dae" />
            </geometry>
        </collision>
        <visual name="arm_1_link_visual">
            <origin xyz="0.006175 -0.058501 0.018013" rpy="-1.570551 3.144842 0.056227" />
            <geometry>
                <mesh filename="./robomaster_ep_arm_1_link_visual_vis_1.dae" />
            </geometry>
            <material name="arm_1_link_visual_material">
                <color rgba="0.028175 0.028000 0.028175 1.0" />
            </material>
        </visual>
        <visual name="arm_1_link_visual">
            <origin xyz="0.006175 -0.058501 0.018013" rpy="-1.570551 3.144842 0.056227" />
            <geometry>
                <mesh filename="./robomaster_ep_arm_1_link_visual_vis_2.dae" />
            </geometry>
            <material name="arm_1_link_visual_material">
                <color rgba="1.000000 1.000000 1.000000 1.0" />
            </material>
        </visual>
    </link>
    <joint type="continuous" name="arm_2_link">
        <axis xyz="0 0 1" />
        <parent link="arm_1_link_respondable" />
        <child link="arm_2_link_respondable" />
        <origin xyz="0.001870 -0.121024 0.043866" rpy="-3.141593 3.141593 3.141593" />
    </joint>
    <link name="arm_2_link_respondable">
        <collision name="arm_2_link_respondable">
            <origin xyz="0.037006 0.006990 -0.020273" rpy="1.571916 3.141590 2.055180" />
            <geometry>
                <mesh filename="./robomaster_ep_arm_2_link_respondable_coll_1.dae" />
            </geometry>
        </collision>
        <visual name="arm_2_link_visual">
            <origin xyz="0.038093 0.004886 -0.017408" rpy="1.570603 3.141592 2.056293" />
            <geometry>
                <mesh filename="./robomaster_ep_arm_2_link_visual_vis_1.dae" />
            </geometry>
            <material name="arm_2_link_visual_material">
                <color rgba="1.000000 1.000000 1.000000 1.0" />
            </material>
        </visual>
        <visual name="arm_2_link_visual">
            <origin xyz="0.038093 0.004886 -0.017408" rpy="1.570603 3.141592 2.056293" />
            <geometry>
                <mesh filename="./robomaster_ep_arm_2_link_visual_vis_2.dae" />
            </geometry>
            <material name="arm_2_link_visual_material">
                <color rgba="1.000000 1.000000 1.000000 1.0" />
            </material>
        </visual>
        <visual name="arm_2_link_visual">
            <origin xyz="0.038093 0.004886 -0.017408" rpy="1.570603 3.141592 2.056293" />
            <geometry>
                <mesh filename="./robomaster_ep_arm_2_link_visual_vis_3.dae" />
            </geometry>
            <material name="arm_2_link_visual_material">
                <color rgba="1.000000 1.000000 1.000000 1.0" />
            </material>
        </visual>
    </link>
    <joint type="continuous" name="endpoint_bracket_link">
        <axis xyz="0 0 1" />
        <parent link="arm_2_link_respondable" />
        <child link="endpoint_bracket_link_respondable" />
        <origin xyz="0.105856 0.056109 0.006752" rpy="3.141593 3.141593 -3.141593" />
    </joint>
    <link name="endpoint_bracket_link_respondable">
        <collision name="endpoint_bracket_link_respondable">
            <origin xyz="0.010956 -0.008580 -0.026963" rpy="3.141592 3.141493 -3.141144" />
            <geometry>
                <mesh filename="./robomaster_ep_endpoint_bracket_link_respondable_coll_1.dae" />
            </geometry>
        </collision>
        <visual name="endpoint_bracket_link_visual">
            <origin xyz="0.011018 -0.008561 -0.025835" rpy="3.141592 3.141494 -3.141146" />
            <geometry>
                <mesh filename="./robomaster_ep_endpoint_bracket_link_visual_vis_1.dae" />
            </geometry>
            <material name="endpoint_bracket_link_visual_material">
                <color rgba="1.000000 1.000000 1.000000 1.0" />
            </material>
        </visual>
    </link>
    <joint type="continuous" name="rod_1_link">
        <axis xyz="0 0 1" />
        <parent link="endpoint_bracket_link_respondable" />
        <child link="rod_1_link_respondable" />
        <origin xyz="0.013458 -0.021307 -0.054097" rpy="-3.141593 3.141593 3.120300" />
    </joint>
    <link name="rod_1_link_respondable">
        <collision name="rod_1_link_respondable">
            <origin xyz="-0.050842 -0.031213 0.000000" rpy="-1.118678 4.712385 -1.517352" />
            <geometry>
                <mesh filename="./robomaster_ep_rod_1_link_respondable_coll_1.dae" />
            </geometry>
        </collision>
        <visual name="rod_1_link_visual">
            <origin xyz="-0.050750 -0.031179 -0.000002" rpy="0.488407 4.712387 -3.123125" />
            <geometry>
                <mesh filename="./robomaster_ep_rod_1_link_visual_vis_1.dae" />
            </geometry>
            <material name="rod_1_link_visual_material">
                <color rgba="1.000000 1.000000 1.000000 1.0" />
            </material>
        </visual>
    </link>
    <joint type="fixed" name="camera_attach">
        <axis xyz="0 0 1" />
        <parent link="arm_2_link_respondable" />
        <child link="camera_link_visual" />
        <origin xyz="0.004019 -0.034011 -0.020260" rpy="-1.570796 3.141593 -3.001966" />
    </joint>
    <link name="camera_link_visual">
        <visual name="camera_link_visual">
            <origin xyz="-0.000648 0.000667 0.013564" rpy="1.570796 3.124139 0.000000" />
            <geometry>
                <mesh filename="./robomaster_ep_camera_link_visual_vis_1.dae" />
            </geometry>
            <material name="camera_link_visual_material">
                <color rgba="0.020166 0.011713 0.029923 1.0" />
            </material>
        </visual>
    </link>
    <joint type="continuous" name="triangle_link">
        <axis xyz="0 0 1" />
        <parent link="arm_1_link_respondable" />
        <child link="triangle_link_respondable" />
        <origin xyz="0.002022 -0.121233 -0.007103" rpy="-3.141592 3.141593 -2.891312" />
    </joint>
    <link name="triangle_link_respondable">
        <collision name="triangle_link_respondable">
            <origin xyz="-0.014028 -0.018759 0.000005" rpy="-1.954402 1.571449 1.570213" />
            <geometry>
                <mesh filename="./robomaster_ep_triangle_link_respondable_coll_1.dae" />
            </geometry>
        </collision>
        <visual name="triangle_link_visual">
            <origin xyz="-0.014063 -0.018900 0.000005" rpy="-1.953610 1.571449 1.570500" />
            <geometry>
                <mesh filename="./robomaster_ep_triangle_link_visual_vis_1.dae" />
            </geometry>
            <material name="triangle_link_visual_material">
                <color rgba="1.000000 1.000000 1.000000 1.0" />
            </material>
        </visual>
    </link>
    <joint type="continuous" name="rod_2_link">
        <axis xyz="0 0 1" />
        <parent link="arm_base_link_respondable" />
        <child link="rod_2_link_respondable" />
        <origin xyz="-0.055478 -0.029070 -0.022428" rpy="-1.570813 4.702964 0.000017" />
    </joint>
    <link name="rod_2_link_respondable">
        <collision name="rod_2_link_respondable">
            <origin xyz="-0.000690 -0.059576 -0.000000" rpy="3.028820 1.570851 1.491040" />
            <geometry>
                <mesh filename="./robomaster_ep_rod_2_link_respondable_coll_1.dae" />
            </geometry>
        </collision>
        <visual name="rod_2_link_visual">
            <origin xyz="-0.000702 -0.059522 0.000000" rpy="3.104893 1.570853 1.566134" />
            <geometry>
                <mesh filename="./robomaster_ep_rod_2_link_visual_vis_1.dae" />
            </geometry>
            <material name="rod_2_link_visual_material">
                <color rgba="1.000000 1.000000 1.000000 1.0" />
            </material>
        </visual>
    </link>
    <joint type="revolute" name="servo_motor_0">
        <axis xyz="0 0 1" />
        <limit effort="1000.0" lower="-0.79936075210571" velocity="5.1312680244446" upper="5.4838247299194" />
        <parent link="arm_base_link_respondable" />
        <child link="rod_link_respondable" />
        <origin xyz="-0.031923 0.021424 0.009805" rpy="-1.570797 -1.570796 0.000000" />
    </joint>
    <link name="rod_link_respondable">
        <inertial>
            <origin xyz="-0.000081 -0.000086 0.002379" rpy="-2.649286 -1.570796 0.000000" />
            <inertia ixx="0.00020289999408998" ixy="0.0003023547012067" ixz="-0.00016216980880584" iyy="0.00075754317529392" iyz="8.1931339617662e-05" izz="0.00086635430723312" />
            <mass value="0.010999999940395" />
        </inertial>
        <collision name="rod_link_respondable">
            <origin xyz="-0.020399 -0.011337 0.002379" rpy="-2.649286 -1.570796 0.000000" />
            <geometry>
                <mesh filename="./robomaster_ep_rod_link_respondable_coll_1.dae" />
            </geometry>
        </collision>
        <visual name="rod_link_visual">
            <origin xyz="-0.020597 -0.011197 0.001658" rpy="-1.092504 4.712387 1.610207" />
            <geometry>
                <mesh filename="./robomaster_ep_rod_link_visual_vis_1.dae" />
            </geometry>
            <material name="rod_link_visual_material">
                <color rgba="1.000000 1.000000 1.000000 1.0" />
            </material>
        </visual>
    </link>
    <joint type="revolute" name="rod_3_link">
        <axis xyz="0 0 1" />
        <limit effort="1000.0" lower="-0.34732049703598" velocity="3.1415927410126" upper="1.2147491574287" />
        <parent link="rod_link_respondable" />
        <child link="rod_3_link_respondable" />
        <origin xyz="-0.042397 -0.022313 0.000453" rpy="-3.141593 3.141593 3.141593" />
    </joint>
    <link name="rod_3_link_respondable">
        <inertial>
            <origin xyz="-0.000357 -0.000168 0.000010" rpy="3.107216 1.570851 1.559078" />
            <inertia ixx="0.0058869943594265" ixy="4.3079325159261e-07" ixz="-1.9013833819694e-05" iyy="0.0059170696757544" iyz="0.00013330729820632" izz="3.7523029161263e-05" />
            <mass value="0.012000000104308" />
        </inertial>
        <collision name="rod_3_link_respondable">
            <origin xyz="-0.001156 -0.060516 0.000009" rpy="3.107216 1.570851 1.559078" />
            <geometry>
                <mesh filename="./robomaster_ep_rod_3_link_respondable_coll_1.dae" />
            </geometry>
        </collision>
        <visual name="rod_3_link_visual">
            <origin xyz="-0.001198 -0.060431 -0.000001" rpy="3.115884 1.570852 1.564259" />
            <geometry>
                <mesh filename="./robomaster_ep_rod_3_link_visual_vis_1.dae" />
            </geometry>
            <material name="rod_3_link_visual_material">
                <color rgba="1.000000 1.000000 1.000000 1.0" />
            </material>
        </visual>
    </link>
    <joint type="fixed" name="extension_base_joint">
        <axis xyz="0 0 1" />
        <parent link="robot_base" />
        <child link="extension_base_link_respondable" />
        <origin xyz="-0.358214 0.125838 0.107186" rpy="-0.004234 1.585757 -0.003830" />
    </joint>
    <link name="extension_base_link_respondable">
        <inertial>
            <origin xyz="-0.004310 -0.000011 0.004419" rpy="-0.000000 3.141593 0.000000" />
            <inertia ixx="0.0022399987531521" ixy="-1.9554282664526e-11" ixz="-2.0007677998689e-19" iyy="0.00091999895372175" iyz="-5.9663003559816e-14" izz="0.0013300013470108" />
            <mass value="0.21999999880791" />
        </inertial>
        <collision name="extension_base_link_respondable">
            <origin xyz="-0.004310 -0.000011 0.004419" rpy="0.000000 -1.570796 0.000000" />
            <geometry>
                <box size="0.279694 0.231779 0.013000" />
            </geometry>
        </collision>
        <collision name="extension_base_link_respondable">
            <origin xyz="-0.039066 0.000021 -0.100668" rpy="0.000000 -1.570796 0.000000" />
            <geometry>
                <box size="0.104444 0.045000 0.002000" />
            </geometry>
        </collision>
        <visual name="extension_base_link_visual">
            <origin xyz="-0.015552 -0.000011 -0.004337" rpy="0.000235 3.145476 -0.000324" />
            <geometry>
                <mesh filename="./robomaster_ep_extension_base_link_visual_vis_1.dae" />
            </geometry>
            <material name="extension_base_link_visual_material">
                <color rgba="0.028175 0.028000 0.028175 1.0" />
            </material>
        </visual>
        <visual name="extension_base_link_visual">
            <origin xyz="-0.015552 -0.000011 -0.004337" rpy="0.000235 3.145476 -0.000324" />
            <geometry>
                <mesh filename="./robomaster_ep_extension_base_link_visual_vis_2.dae" />
            </geometry>
            <material name="extension_base_link_visual_material">
                <color rgba="0.028175 0.028000 0.028175 1.0" />
            </material>
        </visual>
    </link>
    <joint type="continuous" name="front_left_wheel_joint">
        <axis xyz="0 0 1" />
        <parent link="robot_base" />
        <child link="front_left_wheel_link_respondable" />
        <origin xyz="-0.249897 0.224836 0.050372" rpy="1.570859 3.126631 -3.141188" />
    </joint>
    <link name="front_left_wheel_link_respondable">
        <inertial>
            <origin xyz="-0.000210 0.000415 0.000053" rpy="-1.570796 3.141593 3.141592" />
            <inertia ixx="0.00019999955699974" ixy="1.1641466120195e-14" ixz="-5.9837115865974e-13" iyy="0.00012000005669357" iyz="-8.7074804302154e-23" izz="0.00012000005669357" />
            <mass value="0.16200000047684" />
        </inertial>
        <collision name="front_left_wheel_link_respondable">
            <origin xyz="0.000000 -0.000000 -0.000000" rpy="-1.570796 3.141593 3.141592" />
            <geometry>
                <sphere radius="0.025000000372529" />
            </geometry>
        </collision>
        <visual name="front_left_wheel_link_visual">
            <origin xyz="-0.000227 0.000356 0.000053" rpy="2.815621 1.571451 1.570543" />
            <geometry>
                <mesh filename="./robomaster_ep_front_left_wheel_link_visual_vis_1.dae" />
            </geometry>
            <material name="front_left_wheel_link_visual_material">
                <color rgba="0.273909 0.273909 0.273909 1.0" />
            </material>
        </visual>
        <visual name="front_left_wheel_link_visual">
            <origin xyz="-0.000227 0.000356 0.000053" rpy="2.815621 1.571451 1.570543" />
            <geometry>
                <mesh filename="./robomaster_ep_front_left_wheel_link_visual_vis_2.dae" />
            </geometry>
            <material name="front_left_wheel_link_visual_material">
                <color rgba="0.064010 0.064010 0.064010 1.0" />
            </material>
        </visual>
    </link>
    <joint type="continuous" name="front_left_wheel_inner_joint">
        <axis xyz="0 0 1" />
        <parent link="front_left_wheel_link_respondable" />
        <child link="front_left_wheel_inner_link_respondable" />
        <origin xyz="0.000000 -0.000000 -0.000000" rpy="-2.526113 3.665191 2.186276" />
    </joint>
    <link name="front_left_wheel_inner_link_respondable">
        <inertial>
            <origin xyz="-0.000442 0.000144 0.000053" rpy="-1.570796 2.356195 -2.356195" />
            <inertia ixx="1.0000000251457e-05" ixy="1.8305675243518e-31" ixz="-7.9522146391448e-30" iyy="1.0000000251457e-05" iyz="1.6871276897786e-29" izz="1.0000000251457e-05" />
            <mass value="0.0099999997764826" />
        </inertial>
        <collision name="front_left_wheel_inner_link_respondable">
            <origin xyz="-0.000442 0.000144 0.000053" rpy="-1.570796 2.356195 -2.356195" />
            <geometry>
                <sphere radius="0.050000000745058" />
            </geometry>
        </collision>
    </link>
    <joint type="continuous" name="front_right_wheel_joint">
        <axis xyz="0 0 1" />
        <parent link="robot_base" />
        <child link="front_right_wheel_link_respondable" />
        <origin xyz="-0.249816 0.024836 0.050359" rpy="1.570859 3.126631 -3.141188" />
    </joint>
    <link name="front_right_wheel_link_respondable">
        <inertial>
            <origin xyz="0.000224 0.000097 -0.000135" rpy="-1.570796 3.141593 3.141592" />
            <inertia ixx="0.00019999955699974" ixy="1.1641466120195e-14" ixz="-5.9837115865974e-13" iyy="0.00012000005669357" iyz="-8.7074804302154e-23" izz="0.00012000005669357" />
            <mass value="0.16200000047684" />
        </inertial>
        <collision name="front_right_wheel_link_respondable">
            <origin xyz="-0.000000 -0.000000 -0.000000" rpy="-1.570796 3.141593 3.141592" />
            <geometry>
                <sphere radius="0.025000000372529" />
            </geometry>
        </collision>
        <visual name="front_right_wheel_link_visual">
            <origin xyz="0.000299 -0.000095 -0.000120" rpy="-2.453966 1.572337 2.544490" />
            <geometry>
                <mesh filename="./robomaster_ep_front_right_wheel_link_visual_vis_1.dae" />
            </geometry>
            <material name="front_right_wheel_link_visual_material">
                <color rgba="0.064010 0.064010 0.064010 1.0" />
            </material>
        </visual>
        <visual name="front_right_wheel_link_visual">
            <origin xyz="0.000299 -0.000095 -0.000120" rpy="-2.453966 1.572337 2.544490" />
            <geometry>
                <mesh filename="./robomaster_ep_front_right_wheel_link_visual_vis_2.dae" />
            </geometry>
            <material name="front_right_wheel_link_visual_material">
                <color rgba="0.273909 0.273909 0.273909 1.0" />
            </material>
        </visual>
    </link>
    <joint type="continuous" name="front_right_wheel_inner_joint">
        <axis xyz="0 0 1" />
        <parent link="front_right_wheel_link_respondable" />
        <child link="front_right_wheel_inner_link_respondable" />
        <origin xyz="-0.000000 -0.000000 -0.000000" rpy="-0.615480 2.617994 2.186276" />
    </joint>
    <link name="front_right_wheel_inner_link_respondable">
        <inertial>
            <origin xyz="0.000248 -0.000111 0.000063" rpy="1.570796 2.356194 2.356194" />
            <inertia ixx="1.0000000251457e-05" ixy="1.8305675243518e-31" ixz="-7.9522146391448e-30" iyy="1.0000000251457e-05" iyz="1.6871276897786e-29" izz="1.0000000251457e-05" />
            <mass value="0.0099999997764826" />
        </inertial>
        <collision name="front_right_wheel_inner_link_respondable">
            <origin xyz="0.000248 -0.000111 0.000063" rpy="1.570796 2.356194 2.356194" />
            <geometry>
                <sphere radius="0.050000000745058" />
            </geometry>
        </collision>
    </link>
    <joint type="fixed" name="intelligent_controller_joint">
        <axis xyz="0 0 1" />
        <parent link="robot_base" />
        <child link="intelligent_controller_link_respondable" />
        <origin xyz="-0.482905 0.127221 0.171416" rpy="-0.004234 1.585757 -0.003830" />
    </joint>
    <link name="intelligent_controller_link_respondable">
        <inertial>
            <origin xyz="-0.000000 0.000000 0.000000" rpy="0.000000 -1.570796 0.000000" />
            <inertia ixx="0.0010000007156864" ixy="1.1023513752748e-29" ixz="-2.0247384601913e-27" iyy="0.0010000007156864" iyz="-1.8605488208292e-27" izz="0.0010000007156864" />
            <mass value="0.093000002205372" />
        </inertial>
        <collision name="intelligent_controller_link_respondable">
            <origin xyz="0.011384 -0.000020 0.023166" rpy="0.000000 -1.570796 0.000000" />
            <geometry>
                <box size="0.108973 0.059103 0.022915" />
            </geometry>
        </collision>
        <visual name="intelligent_controller_link_visual">
            <origin xyz="-0.021132 -0.000326 0.023085" rpy="3.139521 3.141593 -1.570763" />
            <geometry>
                <mesh filename="./robomaster_ep_intelligent_controller_link_visual_vis_1.dae" />
            </geometry>
            <material name="intelligent_controller_link_visual_material">
                <color rgba="1.000000 1.000000 1.000000 1.0" />
            </material>
        </visual>
        <visual name="intelligent_controller_link_visual">
            <origin xyz="-0.021132 -0.000326 0.023085" rpy="3.139521 3.141593 -1.570763" />
            <geometry>
                <mesh filename="./robomaster_ep_intelligent_controller_link_visual_vis_2.dae" />
            </geometry>
            <material name="intelligent_controller_link_visual_material">
                <color rgba="1.000000 1.000000 1.000000 1.0" />
            </material>
        </visual>
        <visual name="intelligent_controller_link_visual">
            <origin xyz="-0.021132 -0.000326 0.023085" rpy="3.139521 3.141593 -1.570763" />
            <geometry>
                <mesh filename="./robomaster_ep_intelligent_controller_link_visual_vis_3.dae" />
            </geometry>
            <material name="intelligent_controller_link_visual_material">
                <color rgba="1.000000 1.000000 1.000000 1.0" />
            </material>
        </visual>
    </link>
    <joint type="continuous" name="rear_left_wheel_joint">
        <axis xyz="0 0 1" />
        <parent link="robot_base" />
        <child link="rear_left_wheel_link_respondable" />
        <origin xyz="-0.449875 0.224755 0.053364" rpy="1.570859 3.126631 -3.141188" />
    </joint>
    <link name="rear_left_wheel_link_respondable">
        <inertial>
            <origin xyz="-0.000257 -0.000323 -0.000094" rpy="-1.570796 3.141593 3.141592" />
            <inertia ixx="0.00019999955699974" ixy="1.1641466120195e-14" ixz="-5.9837115865974e-13" iyy="0.00012000005669357" iyz="-8.7074804302154e-23" izz="0.00012000005669357" />
            <mass value="0.16200000047684" />
        </inertial>
        <collision name="rear_left_wheel_link_respondable">
            <origin xyz="0.000000 -0.000000 0.000000" rpy="-1.570796 3.141593 3.141592" />
            <geometry>
                <sphere radius="0.025000000372529" />
            </geometry>
        </collision>
        <visual name="rear_left_wheel_link_visual">
            <origin xyz="-0.000254 -0.000220 -0.000095" rpy="3.110271 1.571449 1.570639" />
            <geometry>
                <mesh filename="./robomaster_ep_rear_left_wheel_link_visual_vis_1.dae" />
            </geometry>
            <material name="rear_left_wheel_link_visual_material">
                <color rgba="0.064010 0.064010 0.064010 1.0" />
            </material>
        </visual>
        <visual name="rear_left_wheel_link_visual">
            <origin xyz="-0.000254 -0.000220 -0.000095" rpy="3.110271 1.571449 1.570639" />
            <geometry>
                <mesh filename="./robomaster_ep_rear_left_wheel_link_visual_vis_2.dae" />
            </geometry>
            <material name="rear_left_wheel_link_visual_material">
                <color rgba="0.273909 0.273909 0.273909 1.0" />
            </material>
        </visual>
    </link>
    <joint type="continuous" name="rear_left_wheel_inner_joint">
        <axis xyz="0 0 1" />
        <parent link="rear_left_wheel_link_respondable" />
        <child link="rear_left_wheel_inner_link_respondable" />
        <origin xyz="0.000000 -0.000000 0.000000" rpy="-2.526112 2.617994 -2.186276" />
    </joint>
    <link name="rear_left_wheel_inner_link_respondable">
        <inertial>
            <origin xyz="-0.000310 -0.000147 -0.000248" rpy="-1.570796 3.926991 2.356194" />
            <inertia ixx="1.0000000251457e-05" ixy="1.8305675243518e-31" ixz="-7.9522146391448e-30" iyy="1.0000000251457e-05" iyz="1.6871276897786e-29" izz="1.0000000251457e-05" />
            <mass value="0.0099999997764826" />
        </inertial>
        <collision name="rear_left_wheel_inner_link_respondable">
            <origin xyz="-0.000310 -0.000147 -0.000248" rpy="-1.570796 3.926991 2.356194" />
            <geometry>
                <sphere radius="0.050000000745058" />
            </geometry>
        </collision>
    </link>
    <joint type="continuous" name="rear_right_wheel_joint">
        <axis xyz="0 0 1" />
        <parent link="robot_base" />
        <child link="rear_right_wheel_link_respondable" />
        <origin xyz="-0.449794 0.024755 0.053351" rpy="1.570859 3.126631 -3.141188" />
    </joint>
    <link name="rear_right_wheel_link_respondable">
        <inertial>
            <origin xyz="-0.000131 -0.000202 0.000195" rpy="-1.570796 3.141593 3.141592" />
            <inertia ixx="0.00019999955699974" ixy="1.1641466120195e-14" ixz="-5.9837115865974e-13" iyy="0.00012000005669357" iyz="-8.7074804302154e-23" izz="0.00012000005669357" />
            <mass value="0.16200000047684" />
        </inertial>
        <collision name="rear_right_wheel_link_respondable">
            <origin xyz="0.000000 0.000000 0.000000" rpy="-1.570796 3.141593 3.141592" />
            <geometry>
                <sphere radius="0.025000000372529" />
            </geometry>
        </collision>
        <visual name="rear_right_wheel_link_visual">
            <origin xyz="-0.000125 -0.000190 0.000195" rpy="2.812002 1.571451 1.571450" />
            <geometry>
                <mesh filename="./robomaster_ep_rear_right_wheel_link_visual_vis_1.dae" />
            </geometry>
            <material name="rear_right_wheel_link_visual_material">
                <color rgba="0.064010 0.064010 0.064010 1.0" />
            </material>
        </visual>
        <visual name="rear_right_wheel_link_visual">
            <origin xyz="-0.000125 -0.000190 0.000195" rpy="2.812002 1.571451 1.571450" />
            <geometry>
                <mesh filename="./robomaster_ep_rear_right_wheel_link_visual_vis_2.dae" />
            </geometry>
            <material name="rear_right_wheel_link_visual_material">
                <color rgba="0.273909 0.273909 0.273909 1.0" />
            </material>
        </visual>
    </link>
    <joint type="continuous" name="rear_right_wheel_inner_joint">
        <axis xyz="0 0 1" />
        <parent link="rear_right_wheel_link_respondable" />
        <child link="rear_right_wheel_inner_link_respondable" />
        <origin xyz="0.000000 0.000000 0.000000" rpy="-0.615479 3.665192 -2.186276" />
    </joint>
    <link name="rear_right_wheel_inner_link_respondable">
        <inertial>
            <origin xyz="0.000050 -0.000236 0.000195" rpy="1.570796 3.926991 -2.356194" />
            <inertia ixx="1.0000000251457e-05" ixy="1.8305675243518e-31" ixz="-7.9522146391448e-30" iyy="1.0000000251457e-05" iyz="1.6871276897786e-29" izz="1.0000000251457e-05" />
            <mass value="0.0099999997764826" />
        </inertial>
        <collision name="rear_right_wheel_inner_link_respondable">
            <origin xyz="0.000050 -0.000236 0.000195" rpy="1.570796 3.926991 -2.356194" />
            <geometry>
                <sphere radius="0.050000000745058" />
            </geometry>
        </collision>
    </link>
</robot>
